<?xml version="1.0" ?>
<!-- =================================================================================== -->
<!-- |    This document was autogenerated by xacro from anymal_coyote_drs.urdf.xacro   | -->
<!-- |    EDITING THIS FILE BY HAND IS NOT RECOMMENDED                                 | -->
<!-- =================================================================================== -->
<!-- This file contains the description of the ANYmal robot. -->
<robot name="anymal">
  <!-- Colors -->
  <material name="anymal_material">
    <color rgba="0.7 0.7 0.7 1.0"/>
  </material>
  <gazebo>
    <plugin filename="libanymal_gazebo.so" name="anymal_gazebo_ros_control">
      <robotNamespace>anymal</robotNamespace>
      <!-- Currently unused -->
      <robotDescription>anymal_description</robotDescription>
      <robotBaseLink>base</robotBaseLink>
    </plugin>
    <plugin filename="libgazebo_ros_p3d.so" name="gazebo_robot_pose_publisher">
      <alwaysOn>true</alwaysOn>
      <robotNamespace>anymal</robotNamespace>
      <updateRate>400.0</updateRate>
      <bodyName>base</bodyName>
      <topicName>pose_in_sim_world</topicName>
      <gaussianNoise>0</gaussianNoise>
      <frameName>world</frameName>
      <xyzOffsets>0 0 0</xyzOffsets>
      <rpyOffsets>0 0 0</rpyOffsets>
    </plugin>
  </gazebo>
  <!-- [kg * m^2] -->
  <!-- [m] -->
  <!-- measured -->
  <!-- Base link -->
  <link name="base">
    <visual>
      <origin rpy="0 0 0" xyz="0 0 0"/>
      <geometry>
        <mesh filename="package://anymal_c/urdf/base/base_3_1_1_mesh.dae" scale="1.0 1.0     1.0"/>
      </geometry>
    </visual>
    <collision>
      <origin rpy="0 0 0" xyz="0 0 0"/>
      <geometry>
        <box size="0.58 0.14 0.18"/>
      </geometry>
    </collision>
    <collision>
      <origin rpy="0 1.5707963267948966 0" xyz="0.21749999999999997 0.07 0"/>
      <geometry>
        <cylinder length="0.145" radius="0.09"/>
      </geometry>
    </collision>
    <collision>
      <origin rpy="0 1.5707963267948966 0" xyz="-0.21749999999999997 0.07 0"/>
      <geometry>
        <cylinder length="0.145" radius="0.09"/>
      </geometry>
    </collision>
    <collision>
      <origin rpy="0 1.5707963267948966 0" xyz="0.21749999999999997 -0.07 0"/>
      <geometry>
        <cylinder length="0.145" radius="0.09"/>
      </geometry>
    </collision>
    <collision>
      <origin rpy="0 1.5707963267948966 0" xyz="-0.21749999999999997 -0.07 0"/>
      <geometry>
        <cylinder length="0.145" radius="0.09"/>
      </geometry>
    </collision>
    <!-- Shell self filtering -->
    <self_filter>
      <origin rpy="0 0 0" xyz="0 0 0"/>
      <geometry>
        <box size="1.05 0.5 0.5"/>
      </geometry>
    </self_filter>
  </link>
  <!-- Fixed joint to add front handle link -->
  <joint name="base_to_front_handle" type="fixed">
    <parent link="base"/>
    <child link="front_handle"/>
    <origin rpy="0 0 0" xyz="0.36 0 0.13"/>
  </joint>
  <!-- Front handle link -->
  <!-- Added as a separate link due to limitation in point_cloud_self_filter -->
  <link name="front_handle">
    <collision>
      <origin rpy="0 0 0" xyz="0.0 0 0.015"/>
      <geometry>
        <box size="0.1 0.18 0.13"/>
      </geometry>
    </collision>
    <self_filter>
      <origin rpy="0 0 0" xyz="0.0 0 0.015"/>
      <geometry>
        <box size="0.1 0.18 0.13"/>
      </geometry>
    </self_filter>
  </link>
  <!-- Fixed joint to add top shell link -->
  <joint name="base_to_body_top" type="fixed">
    <parent link="base"/>
    <child link="body_top"/>
    <origin rpy="0 0 0" xyz="0 0 0.09"/>
  </joint>
  <!-- Body top link -->
  <!-- Added as a separate link due to limitation in point_cloud_self_filter -->
  <link name="body_top">
    <self_filter>
      <origin rpy="0 0 0" xyz="0 0 0"/>
      <geometry>
        <box size="1.05 0.4 0.005"/>
      </geometry>
    </self_filter>
  </link>
  <!-- Fixed joint to add dummy inertia link -->
  <joint name="base_to_base_inertia" type="fixed">
    <parent link="base"/>
    <child link="base_inertia"/>
    <origin rpy="0 0 0" xyz="0 0 0"/>
  </joint>
  <!-- Dummy inertia link, because KDL cannot have inertia on the base link -->
  <link name="base_inertia">
    <inertial>
      <origin rpy="0 0 0" xyz="-0.018 -0.002 0.024"/>
      <mass value="6.222"/>
      <inertia ixx="0.017938806" ixy="0.00387963" ixz="0.001500772" iyy="0.370887745" iyz="6.8963e-05" izz="0.372497653"/>
    </inertial>
  </link>
  <!-- [kg * m^2] -->
  <!-- Fixed joint base topshell -->
  <joint name="base_top_shell" type="fixed">
    <parent link="base"/>
    <child link="top_shell"/>
    <origin rpy="0 0 0" xyz="0 0 0"/>
  </joint>
  <!-- Top shell link -->
  <link name="top_shell">
    <visual>
      <origin rpy="0 0 0" xyz="0 0 0"/>
      <geometry>
        <mesh filename="package://anymal_c/urdf/base/shell/top_shell_3_1_1_mesh.dae" scale="1.0 1.0 1.0"/>
      </geometry>
    </visual>
    <inertial>
      <origin rpy="0 0 0" xyz="-0.00777 -0.00013 0.06523"/>
      <mass value="0.534"/>
      <inertia ixx="0.00664789486" ixy="1.247923e-05" ixz="0.00053990097" iyy="0.02587392411" iyz="3.7614e-07" izz="0.03152303792"/>
    </inertial>
  </link>
  <!-- [kg * m^2] -->
  <!-- Fixed joint base topshell -->
  <joint name="base_bottom_shell" type="fixed">
    <parent link="base"/>
    <child link="bottom_shell"/>
    <origin rpy="0 0 0" xyz="0 0 0"/>
  </joint>
  <!-- Bottom shell link -->
  <link name="bottom_shell">
    <visual>
      <origin rpy="0 0 0" xyz="0 0 0"/>
      <geometry>
        <mesh filename="package://anymal_c/urdf/base/shell/bottom_shell_3_1_1_mesh.dae" scale="1.0 1.0 1.0"/>
      </geometry>
    </visual>
    <inertial>
      <origin rpy="0 0 0" xyz="-0.00333 1e-05 -0.07705"/>
      <mass value="1.15"/>
      <inertia ixx="0.00927353677" ixy="5.41222e-06" ixz="9.039821e-05" iyy="0.06134388239" iyz="2.3042e-07" izz="0.06853531465"/>
    </inertial>
  </link>
  <!-- [kg * m^2] -->
  <!-- Fixed joint base remote -->
  <joint name="base_remote" type="fixed">
    <parent link="base"/>
    <child link="remote"/>
    <origin rpy="0 0 0" xyz="0 0 0"/>
  </joint>
  <!-- Remote link -->
  <link name="remote">
    <visual>
      <origin rpy="0 0 0" xyz="0 0 0"/>
      <geometry>
        <mesh filename="package://anymal_c/urdf/base/remote/remote_3_1_1_mesh.dae" scale="1.0 1.0     1.0"/>
      </geometry>
    </visual>
    <inertial>
      <origin rpy="0 0 0" xyz="-0.171 0.002 0.096"/>
      <mass value="0.3262"/>
      <inertia ixx="0.000528486" ixy="4.547e-05" ixz="1.10327e-05" iyy="0.001165035" iyz="7.4e-07" izz="0.00124026"/>
    </inertial>
  </link>
  <!-- [kg * m^2] -->
  <!-- Fixed joint base handle -->
  <joint name="base_handle" type="fixed">
    <parent link="base"/>
    <child link="handle"/>
    <origin rpy="0 0 0" xyz="0 0 0.003"/>
  </joint>
  <!-- Handle link -->
  <link name="handle">
    <visual>
      <origin rpy="0 0 0" xyz="0 0 0.003"/>
      <geometry>
        <mesh filename="package://anymal_c/urdf/base/handle/handle_3_1_1_mesh.dae" scale="1.0 1.0     1.0"/>
      </geometry>
    </visual>
    <inertial>
      <origin rpy="0 0 0" xyz="0.37801 0.0 0.1372"/>
      <mass value="0.314"/>
      <inertia ixx="0.001525739" ixy="0.0" ixz="6.272e-05" iyy="0.00071584" iyz="1e-09" izz="0.001164779"/>
    </inertial>
  </link>
  <!-- [m] -->
  <!-- measured -->
  <!-- Fixed joint base face -->
  <joint name="base_face_front" type="fixed">
    <parent link="base"/>
    <child link="face_front"/>
    <origin rpy="0 0 -0.0" xyz="0.4145 0 0"/>
  </joint>
  <!-- Shell link -->
  <link name="face_front">
    <visual>
      <origin rpy="0 0 0" xyz="0 0 0"/>
      <geometry>
        <mesh filename="package://anymal_coyote_drs/urdf/face/face_3_1_1_mesh.dae" scale="1.0 1.0 1.0"/>
      </geometry>
    </visual>
    <collision>
      <origin rpy="0 0 0" xyz="0.055 0 0"/>
      <geometry>
        <box size="0.11 0.14 0.18"/>
      </geometry>
    </collision>
    <collision>
      <origin rpy="0 1.5707963267948966 0" xyz="0.055 0.07 0"/>
      <geometry>
        <cylinder length="0.11" radius="0.09"/>
      </geometry>
    </collision>
    <collision>
      <origin rpy="0 1.5707963267948966 0" xyz="0.055 -0.07 0"/>
      <geometry>
        <cylinder length="0.11" radius="0.09"/>
      </geometry>
    </collision>
    <inertial>
      <origin rpy="0 0 0" xyz="0.042 -0.001 0.004"/>
      <mass value="0.73"/>
      <inertia ixx="0.005238611" ixy="1.7609e-05" ixz="7.2167e-05" iyy="0.002643098" iyz="1.9548e-05" izz="0.004325938"/>
    </inertial>
  </link>
  <!-- [kg * m^2] -->
  <!-- [m] -->
  <!-- Camera joint -->
  <!-- Is located between the two back screw holes at ground level. -->
  <joint name="face_front_to_depth_camera_front_camera" type="fixed">
    <parent link="face_front"/>
    <child link="depth_camera_front_camera"/>
    <origin rpy="0.0 0.5235987755982988 0.0" xyz="0.041 0.0 -0.022"/>
  </joint>
  <!-- Camera link -->
  <link name="depth_camera_front_camera">
    <visual>
      <origin rpy="0 0 0" xyz="0.0 0.0 0.0"/>
      <geometry>
        <mesh filename="package://anymal_c/urdf/base/sensors/depth_camera/realsense_d435_3_1_1_mesh.dae" scale="1.0 1.0 1.0"/>
      </geometry>
    </visual>
    <inertial>
      <origin rpy="0 0 0" xyz="-0.021 -0.002 0.025"/>
      <mass value="0.16043"/>
      <inertia ixx="0.000637051" ixy="0.000484569" ixz="0.000424211" iyy="0.000929402" iyz="5.138e-06" izz="0.000484569"/>
    </inertial>
  </link>
  <!-- Camera parent joint -->
  <!-- Frame lies on the left ir camera according to any_realsense2_camera urdf. -->
  <joint name="depth_camera_front_camera_to_camera_parent" type="fixed">
    <parent link="depth_camera_front_camera"/>
    <child link="depth_camera_front_camera_parent"/>
    <origin rpy="0.0 0.0 0.0" xyz="0.0255 0.0175 0.0"/>
  </joint>
  <!-- Camera parent link -->
  <link name="depth_camera_front_camera_parent"/>
  <!-- simulation or bagfile_is_played -->
  <!-- simulation -->
  <!-- [kg * m^2] -->
  <!-- [m] -->
  <!-- Camera joint -->
  <!-- Is located in the center of the mounting points. -->
  <joint name="face_front_to_wide_angle_camera_front_camera" type="fixed">
    <parent link="face_front"/>
    <child link="wide_angle_camera_front_camera"/>
    <origin rpy="0 0 0" xyz="0.09850 0.0 0.01497"/>
  </joint>
  <!-- Camera link -->
  <link name="wide_angle_camera_front_camera">
    <visual>
      <origin rpy="0 0 0" xyz="0.0 0.0 0.0"/>
      <geometry>
        <mesh filename="package://anymal_c/urdf/base/sensors/wide_angle_camera/blackfly_3_1_1_mesh.dae" scale="1.0 1.0 1.0"/>
      </geometry>
    </visual>
    <inertial>
      <origin rpy="0 0 0" xyz="-0.053 -0.001 0.025"/>
      <mass value="0.287"/>
      <inertia ixx="0.000559232" ixy="1.6875e-05" ixz="0.000423761" iyy="0.000946504" iyz="1.3234e-07" izz="0.000493052"/>
    </inertial>
  </link>
  <!-- Camera parent joint -->
  <joint name="wide_angle_camera_front_camera_to_camera_parent" type="fixed">
    <parent link="wide_angle_camera_front_camera"/>
    <child link="wide_angle_camera_front_camera_parent"/>
    <origin rpy="-1.5707963267948966 0.0 -1.5707963267948966" xyz="-0.00311 0.0 0.0"/>
  </joint>
  <!-- Camera parent link -->
  <link name="wide_angle_camera_front_camera_parent"/>
  <!-- simulation -->
  <!-- [m] -->
  <!-- measured -->
  <!-- Fixed joint base face -->
  <joint name="base_face_rear" type="fixed">
    <parent link="base"/>
    <child link="face_rear"/>
    <origin rpy="0 0 3.141592653589793" xyz="-0.4145 0 0"/>
  </joint>
  <!-- Shell link -->
  <link name="face_rear">
    <visual>
      <origin rpy="0 0 0" xyz="0 0 0"/>
      <geometry>
        <mesh filename="package://anymal_coyote_drs/urdf/face/face_3_1_1_mesh.dae" scale="1.0 1.0 1.0"/>
      </geometry>
    </visual>
    <collision>
      <origin rpy="0 0 0" xyz="0.055 0 0"/>
      <geometry>
        <box size="0.11 0.14 0.18"/>
      </geometry>
    </collision>
    <collision>
      <origin rpy="0 1.5707963267948966 0" xyz="0.055 0.07 0"/>
      <geometry>
        <cylinder length="0.11" radius="0.09"/>
      </geometry>
    </collision>
    <collision>
      <origin rpy="0 1.5707963267948966 0" xyz="0.055 -0.07 0"/>
      <geometry>
        <cylinder length="0.11" radius="0.09"/>
      </geometry>
    </collision>
    <inertial>
      <origin rpy="0 0 0" xyz="0.042 -0.001 0.004"/>
      <mass value="0.73"/>
      <inertia ixx="0.005238611" ixy="1.7609e-05" ixz="7.2167e-05" iyy="0.002643098" iyz="1.9548e-05" izz="0.004325938"/>
    </inertial>
  </link>
  <!-- [kg * m^2] -->
  <!-- [m] -->
  <!-- Camera joint -->
  <!-- Is located between the two back screw holes at ground level. -->
  <joint name="face_rear_to_depth_camera_rear_camera" type="fixed">
    <parent link="face_rear"/>
    <child link="depth_camera_rear_camera"/>
    <origin rpy="0.0 0.5235987755982988 0.0" xyz="0.041 0.0 -0.022"/>
  </joint>
  <!-- Camera link -->
  <link name="depth_camera_rear_camera">
    <visual>
      <origin rpy="0 0 0" xyz="0.0 0.0 0.0"/>
      <geometry>
        <mesh filename="package://anymal_c/urdf/base/sensors/depth_camera/realsense_d435_3_1_1_mesh.dae" scale="1.0 1.0 1.0"/>
      </geometry>
    </visual>
    <inertial>
      <origin rpy="0 0 0" xyz="-0.021 -0.002 0.025"/>
      <mass value="0.16043"/>
      <inertia ixx="0.000637051" ixy="0.000484569" ixz="0.000424211" iyy="0.000929402" iyz="5.138e-06" izz="0.000484569"/>
    </inertial>
  </link>
  <!-- Camera parent joint -->
  <!-- Frame lies on the left ir camera according to any_realsense2_camera urdf. -->
  <joint name="depth_camera_rear_camera_to_camera_parent" type="fixed">
    <parent link="depth_camera_rear_camera"/>
    <child link="depth_camera_rear_camera_parent"/>
    <origin rpy="0.0 0.0 0.0" xyz="0.0255 0.0175 0.0"/>
  </joint>
  <!-- Camera parent link -->
  <link name="depth_camera_rear_camera_parent"/>
  <!-- simulation or bagfile_is_played -->
  <!-- simulation -->
  <!-- [kg * m^2] -->
  <!-- [m] -->
  <!-- Camera joint -->
  <!-- Is located in the center of the mounting points. -->
  <joint name="face_rear_to_wide_angle_camera_rear_camera" type="fixed">
    <parent link="face_rear"/>
    <child link="wide_angle_camera_rear_camera"/>
    <origin rpy="0 0 0" xyz="0.09850 0.0 0.01497"/>
  </joint>
  <!-- Camera link -->
  <link name="wide_angle_camera_rear_camera">
    <visual>
      <origin rpy="0 0 0" xyz="0.0 0.0 0.0"/>
      <geometry>
        <mesh filename="package://anymal_c/urdf/base/sensors/wide_angle_camera/blackfly_3_1_1_mesh.dae" scale="1.0 1.0 1.0"/>
      </geometry>
    </visual>
    <inertial>
      <origin rpy="0 0 0" xyz="-0.053 -0.001 0.025"/>
      <mass value="0.287"/>
      <inertia ixx="0.000559232" ixy="1.6875e-05" ixz="0.000423761" iyy="0.000946504" iyz="1.3234e-07" izz="0.000493052"/>
    </inertial>
  </link>
  <!-- Camera parent joint -->
  <joint name="wide_angle_camera_rear_camera_to_camera_parent" type="fixed">
    <parent link="wide_angle_camera_rear_camera"/>
    <child link="wide_angle_camera_rear_camera_parent"/>
    <origin rpy="-1.5707963267948966 0.0 -1.5707963267948966" xyz="-0.00311 0.0 0.0"/>
  </joint>
  <!-- Camera parent link -->
  <link name="wide_angle_camera_rear_camera_parent"/>
  <!-- simulation -->
  <!-- [kg * m^2] -->
  <!-- Fixed joint base battery -->
  <joint name="base_battery" type="fixed">
    <parent link="base"/>
    <child link="battery"/>
    <origin rpy="0 0 0" xyz="0 0 0"/>
  </joint>
  <!-- Shell link -->
  <link name="battery">
    <visual>
      <origin rpy="0 0 0" xyz="0 0 0"/>
      <geometry>
        <mesh filename="package://anymal_c/urdf/base/battery/battery_3_0_4_mesh.dae" scale="1.0 1.0     1.0"/>
      </geometry>
    </visual>
    <inertial>
      <origin rpy="0 0 0" xyz="-0.00067 -0.00023 -0.03362"/>
      <mass value="5.53425"/>
      <inertia ixx="0.00749474794" ixy="0.00016686282" ixz="7.82763e-05" iyy="0.0722338913" iyz="1.42902e-06" izz="0.07482717535"/>
    </inertial>
  </link>
  <!-- [kg * m^2] -->
  <!-- Fixed joint to add docking  -->
  <joint name="base_to_docking_hatch_cover" type="fixed">
    <parent link="base"/>
    <child link="docking_hatch_cover"/>
    <origin rpy="0 0 0" xyz="0.343 0.0 -0.07"/>
  </joint>
  <!-- Hatch cover link -->
  <link name="docking_hatch_cover">
    <!--  TODO(fgiraldez): add visual    -->
    <inertial>
      <origin rpy="0 0 0" xyz="-0.003 0.0 0.005"/>
      <mass value="0.065"/>
      <inertia ixx="0.00063283" ixy="0.0" ixz="3.45e-07" iyy="0.00110971" iyz="0.0" izz="0.00171883"/>
    </inertial>
  </link>
  <link name="imu_link"/>
  <joint name="imu_joint" type="fixed">
    <parent link="base"/>
    <child link="imu_link"/>
    <origin rpy="0.0 0.0 1.5707963267948966" xyz="0.2488 0.00835 0.04628"/>
  </joint>
  <gazebo reference="imu_joint">
      </gazebo>
  <gazebo>
    <plugin filename="libany_hector_gazebo_ros_imu.so" name="imu_plugin">
      <robotNamespace>sensors</robotNamespace>
      <bodyName>imu_link</bodyName>
      <frameId>imu_link</frameId>
      <topicName>imu</topicName>
      <biasTopicName>imu/bias</biasTopicName>
      <serviceName>imu/calibrate</serviceName>
      <updateRate>400</updateRate>
    </plugin>
  </gazebo>
  <!-- [kg * m^2] -->
  <!-- [m] -->
  <!-- Camera joint -->
  <!-- Is located between the two back screw holes at ground level. -->
  <joint name="base_to_depth_camera_left_camera" type="fixed">
    <parent link="base"/>
    <child link="depth_camera_left_camera"/>
    <origin rpy="0.0 0.5235987755982988 1.5707963267948966" xyz="0.0 0.0722 0.0324"/>
  </joint>
  <!-- Camera link -->
  <link name="depth_camera_left_camera">
    <visual>
      <origin rpy="0 0 0" xyz="0.0 0.0 0.0"/>
      <geometry>
        <mesh filename="package://anymal_c/urdf/base/sensors/depth_camera/realsense_d435_3_1_1_mesh.dae" scale="1.0 1.0 1.0"/>
      </geometry>
    </visual>
    <inertial>
      <origin rpy="0 0 0" xyz="-0.021 -0.002 0.025"/>
      <mass value="0.16043"/>
      <inertia ixx="0.000637051" ixy="0.000484569" ixz="0.000424211" iyy="0.000929402" iyz="5.138e-06" izz="0.000484569"/>
    </inertial>
  </link>
  <!-- Camera parent joint -->
  <!-- Frame lies on the left ir camera according to any_realsense2_camera urdf. -->
  <joint name="depth_camera_left_camera_to_camera_parent" type="fixed">
    <parent link="depth_camera_left_camera"/>
    <child link="depth_camera_left_camera_parent"/>
    <origin rpy="0.0 0.0 0.0" xyz="0.0255 0.0175 0.0"/>
  </joint>
  <!-- Camera parent link -->
  <link name="depth_camera_left_camera_parent"/>
  <!-- simulation or bagfile_is_played -->
  <!-- simulation -->
  <!-- [kg * m^2] -->
  <!-- [m] -->
  <!-- Camera joint -->
  <!-- Is located between the two back screw holes at ground level. -->
  <joint name="base_to_depth_camera_right_camera" type="fixed">
    <parent link="base"/>
    <child link="depth_camera_right_camera"/>
    <origin rpy="0.0 0.5235987755982988 -1.5707963267948966" xyz="0.0 -0.0722 0.0324"/>
  </joint>
  <!-- Camera link -->
  <link name="depth_camera_right_camera">
    <visual>
      <origin rpy="0 0 0" xyz="0.0 0.0 0.0"/>
      <geometry>
        <mesh filename="package://anymal_c/urdf/base/sensors/depth_camera/realsense_d435_3_1_1_mesh.dae" scale="1.0 1.0 1.0"/>
      </geometry>
    </visual>
    <inertial>
      <origin rpy="0 0 0" xyz="-0.021 -0.002 0.025"/>
      <mass value="0.16043"/>
      <inertia ixx="0.000637051" ixy="0.000484569" ixz="0.000424211" iyy="0.000929402" iyz="5.138e-06" izz="0.000484569"/>
    </inertial>
  </link>
  <!-- Camera parent joint -->
  <!-- Frame lies on the left ir camera according to any_realsense2_camera urdf. -->
  <joint name="depth_camera_right_camera_to_camera_parent" type="fixed">
    <parent link="depth_camera_right_camera"/>
    <child link="depth_camera_right_camera_parent"/>
    <origin rpy="0.0 0.0 0.0" xyz="0.0255 0.0175 0.0"/>
  </joint>
  <!-- Camera parent link -->
  <link name="depth_camera_right_camera_parent"/>
  <!-- simulation or bagfile_is_played -->
  <!-- simulation -->
  <!-- Parent to cage joint, located between mounting plate on trunk and the cage -->
  <joint name="base_to_perception_head_cage" type="fixed">
    <parent link="base"/>
    <child link="perception_head_cage"/>
    <origin rpy="0 0 0" xyz="-0.364 0.0 0.0"/>
  </joint>
  <!-- Velodyne cage link -->
  <link name="perception_head_cage">
    <visual>
      <origin rpy="0.0 0.0 0.0" xyz="0.0 0.0 0.0"/>
      <geometry>
        <mesh filename="package://anymal_coyote_drs/urdf/modules/perception_head/perception_head.stl" scale=".001 .001 .001"/>
      </geometry>
      <material name="anymal_material"/>
    </visual>
    <collision>
      <origin rpy="0 0 0" xyz="0.0080435 0.0 0.1614"/>
      <geometry>
        <box size="0.14151 0.21544 0.1768"/>
      </geometry>
    </collision>
    <inertial>
      <mass value="0.3879"/>
      <origin xyz="-0.01163                      -0.0000109                      0.15412"/>
      <inertia ixx="0.011412" ixy="-0.00000037" ixz="-0.00086643" iyy="0.010402" iyz="0.00000038" izz="0.001749"/>
    </inertial>
  </link>
  <!-- [kg * m^2] -->
  <!-- parent to sensor joint -->
  <joint name="perception_head_cage_to_lidar" type="fixed">
    <parent link="perception_head_cage"/>
    <child link="lidar"/>
    <origin rpy="0.0 0.0 -1.57079632679" xyz="0.0 0.0 0.1422"/>
  </joint>
  <!-- Velodyne sensor link -->
  <link name="lidar">
    <inertial>
      <origin rpy="0.0 0.0 0.0" xyz="-0.012 0.001 -0.008"/>
      <mass value="0.695"/>
      <inertia ixx="0.000846765" ixy="6.9565e-05" ixz="0.00027111" iyy="0.001367583" iyz="5.8984e-05" izz="0.001363673"/>
    </inertial>
    <visual>
      <origin xyz="0 0 0"/>
      <geometry>
        <mesh filename="package://anymal_c/urdf/base/sensors/lidar/velodyne_3_1_1_mesh.dae"/>
      </geometry>
    </visual>
  </link>
  <!-- simulation -->
  <!-- IMU link -->
  <link name="imu_sensor_frame"/>
  <joint name="lidar_to_alphasense" type="fixed">
    <parent link="lidar"/>
    <child link="imu_sensor_frame"/>
    <origin rpy="0.0 0.0 0.0" xyz="0.005303 0.03734 0.063319"/>
  </joint>
  <!-- Visualization & Crash Box -->
  <link name="alphasense_mesh">
    <visual>
      <origin rpy="0 0 0" xyz="0 0 0"/>
      <geometry>
        <mesh filename="package://anymal_coyote_drs/urdf/modules/alphasense/alphasense.stl" scale=".001 .001 .001"/>
      </geometry>
      <material name="anymal_material"/>
    </visual>
    <collision>
      <origin rpy="0 0 0" xyz="0.0144025 0.0 0.235"/>
      <geometry>
        <box size="0.128 0.165 0.098"/>
      </geometry>
    </collision>
    <inertial>
      <mass value="0.5"/>
      <origin xyz="0.01243 0.000687 0.23"/>
      <inertia ixx="0.001237" ixy="0.000016" ixz="0.000005" iyy="0.000897" iyz="-0.00001143" izz="0.00149"/>
    </inertial>
  </link>
  <joint name="base_to_alphasense_mesh" type="fixed">
    <parent link="base"/>
    <child link="alphasense_mesh"/>
    <origin rpy="0.0 0.0 0.0" xyz="-0.364 0.0 0.0"/>
  </joint>
  <link name="cam0_sensor_frame"/>
  <joint name="imu_sensor_frame_to_cam0_sensor_frame" type="fixed">
    <parent link="imu_sensor_frame"/>
    <child link="cam0_sensor_frame"/>
    <origin rpy="-1.5720552 -0.0025018 -3.1392056" xyz="0.04537774 -0.07367025 0.0225275"/>
  </joint>
  <!-- simulation -->
  <link name="cam1_sensor_frame"/>
  <joint name="imu_sensor_frame_to_cam1_sensor_frame" type="fixed">
    <parent link="imu_sensor_frame"/>
    <child link="cam1_sensor_frame"/>
    <origin rpy="-1.5748043 -0.0003067 -3.1363186" xyz="-0.0549134 -0.07495668 0.02110043"/>
  </joint>
  <!-- simulation -->
  <link name="cam2_sensor_frame"/>
  <joint name="imu_sensor_frame_to_cam2_sensor_frame" type="fixed">
    <parent link="imu_sensor_frame"/>
    <child link="cam2_sensor_frame"/>
    <origin rpy="-0.0024622 0.0008607 3.1377207" xyz="0.04275491 -0.04977056 0.05808629"/>
  </joint>
  <!-- simulation -->
  <link name="cam3_sensor_frame"/>
  <joint name="imu_sensor_frame_to_cam3_sensor_frame" type="fixed">
    <parent link="imu_sensor_frame"/>
    <child link="cam3_sensor_frame"/>
    <origin rpy="-1.4000444 -0.0045942 -1.568382" xyz="0.06873384 -0.02210412 0.02929201"/>
  </joint>
  <!-- simulation -->
  <link name="cam4_sensor_frame"/>
  <joint name="imu_sensor_frame_to_cam4_sensor_frame" type="fixed">
    <parent link="imu_sensor_frame"/>
    <child link="cam4_sensor_frame"/>
    <origin rpy="-1.5703236 -0.0004822 -3.1378793" xyz="-0.00569282 -0.07527652 0.02277401"/>
  </joint>
  <!-- simulation -->
  <link name="cam5_sensor_frame"/>
  <joint name="imu_sensor_frame_to_cam5_sensor_frame" type="fixed">
    <parent link="imu_sensor_frame"/>
    <child link="cam5_sensor_frame"/>
    <origin rpy="-1.3944719 0.0007604 1.570797" xyz="-0.07630108 -0.01995696 0.03155353"/>
  </joint>
  <!-- simulation -->
  <link name="cam6_sensor_frame"/>
  <joint name="imu_sensor_frame_to_cam6_sensor_frame" type="fixed">
    <parent link="imu_sensor_frame"/>
    <child link="cam6_sensor_frame"/>
    <origin rpy="-0.002681 -0.001708 3.1345393" xyz="-0.0554172 -0.05064799 0.05769353"/>
  </joint>
  <!-- simulation -->
  <!-- Fixed joint base to interface hatch -->
  <joint name="base_to_interface_hatch" type="fixed">
    <parent link="base"/>
    <child link="interface_hatch"/>
    <origin rpy="0 0 0" xyz="0.0 0.0 0.073"/>
  </joint>
  <!-- Interface hatch link -->
  <link name="interface_hatch">
    <visual>
      <origin rpy="0.0 0.0 0.0" xyz="0.0 0.0 0.0"/>
      <geometry>
        <mesh filename="package://anymal_coyote_drs/urdf/modules/interface_hatch/interface_hatch.stl" scale=".001 .001 .001"/>
      </geometry>
      <material name="anymal_material"/>
    </visual>
    <collision>
      <origin rpy="0 0 0" xyz="0.1158036 0.0 0.0245"/>
      <geometry>
        <box size="0.1817832 0.1296570 0.055"/>
      </geometry>
    </collision>
    <inertial>
      <mass value="0.293687504"/>
      <origin xyz="0.115318879473                      0.000251718520                      0.021931226692"/>
      <inertia ixx="0.000687763980844" ixy="-0.000001080796219" ixz="0.000002713907006" iyy="0.001176920719975" iyz="-0.000000364550324" izz="0.001716726006302"/>
    </inertial>
  </link>
  <!-- [kg * m^2] -->
  <!-- Fixed joint base hatch -->
  <joint name="interface_hatch_hatch" type="fixed">
    <parent link="interface_hatch"/>
    <child link="hatch"/>
    <origin rpy="0 0 0" xyz="0.116 0.0 0.0475"/>
  </joint>
  <!-- Hatch link -->
  <link name="hatch">
    <visual>
      <origin rpy="0 0 0" xyz="0 0 0"/>
      <geometry>
        <mesh filename="package://anymal_c/urdf/base/hatch/hatch_3_1_1_mesh.dae" scale="1.0 1.0 1.0"/>
      </geometry>
    </visual>
    <inertial>
      <origin rpy="0 0 0" xyz="0.116 0.0 0.0758"/>
      <mass value="0.142"/>
      <inertia ixx="0.001" ixy="0.0" ixz="0.0" iyy="0.001" iyz="0.0" izz="0.001"/>
    </inertial>
  </link>
  <!--<xacro:hatch/> -->
  <!-- [rad] -->
  <!-- [rad] -->
  <!-- joint base HAA -->
  <joint name="base_LF_HAA" type="fixed">
    <parent link="base"/>
    <child link="LF_HAA"/>
    <origin rpy="2.6179938779914944 0 0.0" xyz="0.2999 0.104 0.0"/>
  </joint>
  <!-- [m] -->
  <!-- [A] -->
  <!-- Drive link -->
  <link name="LF_HAA">
    <visual>
      <origin rpy="0 0 0" xyz="0 0 0"/>
      <geometry>
        <mesh filename="package://anymal_c/urdf/leg/drives/drive_3_0_2_mesh.dae" scale="1.0 1.0     1.0"/>
      </geometry>
    </visual>
    <inertial>
      <origin rpy="0 0 0" xyz="-0.063 7e-05 0.00046"/>
      <mass value="2.04"/>
      <inertia ixx="0.001053013" ixy="4.527e-05" ixz="8.855e-05" iyy="0.001805509" iyz="9.909e-05" izz="0.001765827"/>
    </inertial>
  </link>
  <!-- joint Drive output -->
  <joint name="LF_HAA" type="revolute">
    <parent link="LF_HAA"/>
    <child link="LF_HIP"/>
    <origin rpy="0 0 0" xyz="0 0 0"/>
    <axis xyz="1 0 0"/>
    <limit command_effort="80.0" current="32.0" effort="80.0" gear_velocity="7.5" lower="-0.72" upper="0.49" velocity="7.5"/>
    <dynamics damping="0.0" friction="0.0"/>
  </joint>
  <!-- Drive output link -->
  <link name="LF_HIP">
    <inertial>
      <origin rpy="0 0 0" xyz="0 0 0"/>
      <mass value="0.001"/>
      <inertia ixx="0.000001" ixy="0.0" ixz="0.0" iyy="0.000001" iyz="0.0" izz="0.000001"/>
    </inertial>
  </link>
  <!-- [kg * m^2] -->
  <!-- joint HAA hip -->
  <joint name="LF_HIP_LF_hip_fixed" type="fixed">
    <parent link="LF_HIP"/>
    <child link="LF_hip_fixed"/>
    <origin rpy="-2.6179938779914944 0 0.0" xyz="0 0 0"/>
  </joint>
  <!-- Hip link -->
  <link name="LF_hip_fixed">
    <visual>
      <origin rpy="0 0 0.0" xyz="0 0 0"/>
      <geometry>
        <mesh filename="package://anymal_c/urdf/leg/hip/hip_3_1_1_mesh.dae" scale="1.0 1.0     1.0"/>
      </geometry>
    </visual>
    <inertial>
      <origin rpy="0 0 0" xyz="0.048 0.008 -0.003"/>
      <mass value="0.74"/>
      <inertia ixx="0.001393106" ixy="8.4012e-05" ixz="2.3378e-05" iyy="0.003798579" iyz="7.1319e-05" izz="0.003897509"/>
    </inertial>
  </link>
  <!-- [rad] -->
  <!-- joint hip HFE -->
  <joint name="LF_hip_fixed_LF_HFE" type="fixed">
    <parent link="LF_hip_fixed"/>
    <child link="LF_HFE"/>
    <origin rpy="0 0 1.5707963267948966" xyz="0.0599 0.08381 0.0"/>
  </joint>
  <!-- [m] -->
  <!-- [A] -->
  <!-- Drive link -->
  <link name="LF_HFE">
    <visual>
      <origin rpy="0 0 0" xyz="0 0 0"/>
      <geometry>
        <mesh filename="package://anymal_c/urdf/leg/drives/drive_3_0_2_mesh.dae" scale="1.0 1.0     1.0"/>
      </geometry>
    </visual>
    <collision>
      <origin rpy="0 1.5707963267948966 0" xyz="-0.07 0 0"/>
      <geometry>
        <cylinder length="0.14" radius="0.05"/>
      </geometry>
    </collision>
    <inertial>
      <origin rpy="0 0 0" xyz="-0.063 7e-05 0.00046"/>
      <mass value="2.04"/>
      <inertia ixx="0.001053013" ixy="4.527e-05" ixz="8.855e-05" iyy="0.001805509" iyz="9.909e-05" izz="0.001765827"/>
    </inertial>
  </link>
  <!-- joint Drive output -->
  <joint name="LF_HFE" type="revolute">
    <parent link="LF_HFE"/>
    <child link="LF_THIGH"/>
    <origin rpy="0 0 0" xyz="0 0 0"/>
    <axis xyz="1 0 0"/>
    <limit command_effort="80.0" current="32.0" effort="80.0" gear_velocity="7.5" lower="-9.42477796076938" upper="9.42477796076938" velocity="7.5"/>
    <dynamics damping="0.0" friction="0.0"/>
  </joint>
  <!-- Drive output link -->
  <link name="LF_THIGH">
    <inertial>
      <origin rpy="0 0 0" xyz="0 0 0"/>
      <mass value="0.001"/>
      <inertia ixx="0.000001" ixy="0.0" ixz="0.0" iyy="0.000001" iyz="0.0" izz="0.000001"/>
    </inertial>
  </link>
  <!-- [m] -->
  <!-- measured -->
  <!-- joint HFE thigh -->
  <joint name="LF_THIGH_LF_thigh_fixed" type="fixed">
    <parent link="LF_THIGH"/>
    <child link="LF_thigh_fixed"/>
    <origin rpy="0 0 -1.5707963267948966" xyz="0 0 0"/>
  </joint>
  <!-- Thigh link -->
  <link name="LF_thigh_fixed">
    <visual>
      <origin rpy="0 0 0.0" xyz="0 0 0"/>
      <geometry>
        <mesh filename="package://anymal_c/urdf/leg/thigh/thigh_3_1_1_mesh.dae" scale="1.0 1.0     1.0"/>
      </geometry>
    </visual>
    <!-- Thigh collision -->
    <collision>
      <origin rpy="1.5707963267948966 0 0" xyz="0 0.04 0"/>
      <geometry>
        <cylinder length="0.08" radius="0.065"/>
      </geometry>
    </collision>
    <collision>
      <origin rpy="0 0 0" xyz="0 0.03 -0.1413135"/>
      <geometry>
        <box size="0.07500000000000001 0.06 0.282627"/>
      </geometry>
    </collision>
    <inertial>
      <origin rpy="0 0 0" xyz="0.0 0.018 -0.169"/>
      <mass value="1.03"/>
      <inertia ixx="0.018644469" ixy="5.2e-08" ixz="1.0157e-05" iyy="0.019312599" iyz="0.002520077" izz="0.002838361"/>
    </inertial>
  </link>
  <!-- [rad] -->
  <!-- joint thigh KFE -->
  <joint name="LF_thigh_fixed_LF_KFE" type="fixed">
    <parent link="LF_thigh_fixed"/>
    <child link="LF_KFE"/>
    <origin rpy="0 0 1.5707963267948966" xyz="0.0 0.1003 -0.285"/>
  </joint>
  <!-- [m] -->
  <!-- [A] -->
  <!-- Drive link -->
  <link name="LF_KFE">
    <visual>
      <origin rpy="0 0 0" xyz="0 0 0"/>
      <geometry>
        <mesh filename="package://anymal_c/urdf/leg/drives/drive_3_0_2_mesh.dae" scale="1.0 1.0     1.0"/>
      </geometry>
    </visual>
    <collision>
      <origin rpy="0 1.5707963267948966 0" xyz="-0.07 0 0"/>
      <geometry>
        <cylinder length="0.14" radius="0.05"/>
      </geometry>
    </collision>
    <inertial>
      <origin rpy="0 0 0" xyz="-0.063 7e-05 0.00046"/>
      <mass value="2.04"/>
      <inertia ixx="0.001053013" ixy="4.527e-05" ixz="8.855e-05" iyy="0.001805509" iyz="9.909e-05" izz="0.001765827"/>
    </inertial>
  </link>
  <!-- joint Drive output -->
  <joint name="LF_KFE" type="revolute">
    <parent link="LF_KFE"/>
    <child link="LF_SHANK"/>
    <origin rpy="0 0 0" xyz="0 0 0"/>
    <axis xyz="1 0 0"/>
    <limit command_effort="80.0" current="32.0" effort="80.0" gear_velocity="7.5" lower="-9.42477796076938" upper="9.42477796076938" velocity="7.5"/>
    <dynamics damping="0.0" friction="0.0"/>
  </joint>
  <!-- Drive output link -->
  <link name="LF_SHANK">
    <inertial>
      <origin rpy="0 0 0" xyz="0 0 0"/>
      <mass value="0.001"/>
      <inertia ixx="0.000001" ixy="0.0" ixz="0.0" iyy="0.000001" iyz="0.0" izz="0.000001"/>
    </inertial>
  </link>
  <!-- [m] -->
  <!-- measured -->
  <!-- joint KFE shank -->
  <joint name="LF_shank_LF_shank_fixed" type="fixed">
    <parent link="LF_SHANK"/>
    <child link="LF_shank_fixed"/>
    <origin rpy="0 0 -1.5707963267948966" xyz="0 0 0"/>
  </joint>
  <!-- Shank link -->
  <link name="LF_shank_fixed">
    <visual>
      <origin rpy="0 0 0.0" xyz="0 0 0"/>
      <geometry>
        <mesh filename="package://anymal_c/urdf/leg/shank/shank_3_1_1_mesh.dae" scale="1.0 1.0     1.0"/>
      </geometry>
    </visual>
    <!-- Shank collision -->
    <collision>
      <origin rpy="1.5707963267948966 0 0" xyz="0 0.02 0"/>
      <geometry>
        <cylinder length="0.04" radius="0.06"/>
      </geometry>
    </collision>
    <collision>
      <origin rpy="1.5707963267948966 0 0" xyz="0.057499 0.02 0"/>
      <geometry>
        <box size="0.114998 0.0675 0.04"/>
      </geometry>
    </collision>
    <inertial>
      <origin rpy="0 0 0" xyz="0.03463 0.00688 0.00098"/>
      <mass value="0.33742"/>
      <inertia ixx="0.00032748005" ixy="2.142561e-05" ixz="1.33942e-05" iyy="0.00110974122" iyz="7.601e-08" izz="0.00089388521"/>
    </inertial>
  </link>
  <!-- Leg configurations: xx (knees bent inwards), xo (knees bent backwards) -->
  <!-- joint shank foot -->
  <joint name="LF_shank_fixed_LF_FOOT" type="fixed">
    <parent link="LF_shank_fixed"/>
    <child link="LF_FOOT"/>
    <origin rpy="0 0 0" xyz="0.08795 0.01305 -0.33797"/>
  </joint>
  <!-- Foot link -->
  <link name="LF_FOOT">
    <visual>
      <origin rpy="0 0 -0.7853981633974483" xyz="0 0 0"/>
      <geometry>
        <mesh filename="package://anymal_c/urdf/leg/foot/foot_3_1_1_mesh.dae" scale="1.0 1.0     1.0"/>
      </geometry>
    </visual>
    <!-- Adapter collision -->
    <collision>
      <origin rpy="0 0 0" xyz="0 0 0.168985"/>
      <geometry>
        <cylinder length="0.282504" radius="0.0175"/>
      </geometry>
    </collision>
    <!-- Foot collision -->
    <collision>
      <origin xyz="0 0 0.0225"/>
      <geometry>
        <sphere radius="0.03"/>
      </geometry>
    </collision>
    <inertial>
      <origin rpy="0 0 0" xyz="0.00948 -0.00948 0.1468"/>
      <mass value="0.25"/>
      <inertia ixx="0.00317174097" ixy="2.63048e-06" ixz="6.815581e-05" iyy="0.00317174092" iyz="6.815583e-05" izz="8.319196e-05"/>
    </inertial>
  </link>
  <!-- Gazebo customization -->
  <gazebo reference="LF_FOOT">
    <kp>1000000.0</kp>
    <kd>100.0</kd>
    <mu1>0.8</mu1>
    <mu2>0.8</mu2>
  </gazebo>
  <!-- [rad] -->
  <!-- [rad] -->
  <!-- joint base HAA -->
  <joint name="base_RF_HAA" type="fixed">
    <parent link="base"/>
    <child link="RF_HAA"/>
    <origin rpy="-2.6179938779914944 0 0.0" xyz="0.2999 -0.104 0.0"/>
  </joint>
  <!-- [m] -->
  <!-- [A] -->
  <!-- Drive link -->
  <link name="RF_HAA">
    <visual>
      <origin rpy="0 0 0" xyz="0 0 0"/>
      <geometry>
        <mesh filename="package://anymal_c/urdf/leg/drives/drive_3_0_2_mesh.dae" scale="1.0 1.0     1.0"/>
      </geometry>
    </visual>
    <inertial>
      <origin rpy="0 0 0" xyz="-0.063 7e-05 0.00046"/>
      <mass value="2.04"/>
      <inertia ixx="0.001053013" ixy="4.527e-05" ixz="8.855e-05" iyy="0.001805509" iyz="9.909e-05" izz="0.001765827"/>
    </inertial>
  </link>
  <!-- joint Drive output -->
  <joint name="RF_HAA" type="revolute">
    <parent link="RF_HAA"/>
    <child link="RF_HIP"/>
    <origin rpy="0 0 0" xyz="0 0 0"/>
    <axis xyz="1 0 0"/>
    <limit command_effort="80.0" current="32.0" effort="80.0" gear_velocity="7.5" lower="-0.49" upper="0.72" velocity="7.5"/>
    <dynamics damping="0.0" friction="0.0"/>
  </joint>
  <!-- Drive output link -->
  <link name="RF_HIP">
    <inertial>
      <origin rpy="0 0 0" xyz="0 0 0"/>
      <mass value="0.001"/>
      <inertia ixx="0.000001" ixy="0.0" ixz="0.0" iyy="0.000001" iyz="0.0" izz="0.000001"/>
    </inertial>
  </link>
  <!-- [kg * m^2] -->
  <!-- joint HAA hip -->
  <joint name="RF_HIP_RF_hip_fixed" type="fixed">
    <parent link="RF_HIP"/>
    <child link="RF_hip_fixed"/>
    <origin rpy="2.6179938779914944 0 0.0" xyz="0 0 0"/>
  </joint>
  <!-- Hip link -->
  <link name="RF_hip_fixed">
    <visual>
      <origin rpy="0 0 0.0" xyz="0 0 0"/>
      <geometry>
        <mesh filename="package://anymal_c/urdf/leg/hip/hip_3_1_1_mesh_mirrored.dae" scale="1.0 1.0     1.0"/>
      </geometry>
    </visual>
    <inertial>
      <origin rpy="0 0 0" xyz="0.048 -0.008 -0.003"/>
      <mass value="0.74"/>
      <inertia ixx="0.001393106" ixy="-8.4012e-05" ixz="2.3378e-05" iyy="0.003798579" iyz="-7.1319e-05" izz="0.003897509"/>
    </inertial>
  </link>
  <!-- [rad] -->
  <!-- joint hip HFE -->
  <joint name="RF_hip_fixed_RF_HFE" type="fixed">
    <parent link="RF_hip_fixed"/>
    <child link="RF_HFE"/>
    <origin rpy="0 0 -1.5707963267948966" xyz="0.0599 -0.08381 0.0"/>
  </joint>
  <!-- [m] -->
  <!-- [A] -->
  <!-- Drive link -->
  <link name="RF_HFE">
    <visual>
      <origin rpy="0 0 0" xyz="0 0 0"/>
      <geometry>
        <mesh filename="package://anymal_c/urdf/leg/drives/drive_3_0_2_mesh.dae" scale="1.0 1.0     1.0"/>
      </geometry>
    </visual>
    <collision>
      <origin rpy="0 1.5707963267948966 0" xyz="-0.07 0 0"/>
      <geometry>
        <cylinder length="0.14" radius="0.05"/>
      </geometry>
    </collision>
    <inertial>
      <origin rpy="0 0 0" xyz="-0.063 7e-05 0.00046"/>
      <mass value="2.04"/>
      <inertia ixx="0.001053013" ixy="4.527e-05" ixz="8.855e-05" iyy="0.001805509" iyz="9.909e-05" izz="0.001765827"/>
    </inertial>
  </link>
  <!-- joint Drive output -->
  <joint name="RF_HFE" type="revolute">
    <parent link="RF_HFE"/>
    <child link="RF_THIGH"/>
    <origin rpy="0 0 0" xyz="0 0 0"/>
    <axis xyz="-1 0 0"/>
    <limit command_effort="80.0" current="32.0" effort="80.0" gear_velocity="7.5" lower="-9.42477796076938" upper="9.42477796076938" velocity="7.5"/>
    <dynamics damping="0.0" friction="0.0"/>
  </joint>
  <!-- Drive output link -->
  <link name="RF_THIGH">
    <inertial>
      <origin rpy="0 0 0" xyz="0 0 0"/>
      <mass value="0.001"/>
      <inertia ixx="0.000001" ixy="0.0" ixz="0.0" iyy="0.000001" iyz="0.0" izz="0.000001"/>
    </inertial>
  </link>
  <!-- [m] -->
  <!-- measured -->
  <!-- joint HFE thigh -->
  <joint name="RF_THIGH_RF_thigh_fixed" type="fixed">
    <parent link="RF_THIGH"/>
    <child link="RF_thigh_fixed"/>
    <origin rpy="0 0 1.5707963267948966" xyz="0 0 0"/>
  </joint>
  <!-- Thigh link -->
  <link name="RF_thigh_fixed">
    <visual>
      <origin rpy="0 0 -3.141592653589793" xyz="0 0 0"/>
      <geometry>
        <mesh filename="package://anymal_c/urdf/leg/thigh/thigh_3_1_1_mesh.dae" scale="1.0 1.0     1.0"/>
      </geometry>
    </visual>
    <!-- Thigh collision -->
    <collision>
      <origin rpy="1.5707963267948966 0 0" xyz="0 -0.04 0"/>
      <geometry>
        <cylinder length="0.08" radius="0.065"/>
      </geometry>
    </collision>
    <collision>
      <origin rpy="0 0 0" xyz="0 -0.03 -0.1413135"/>
      <geometry>
        <box size="0.07500000000000001 0.06 0.282627"/>
      </geometry>
    </collision>
    <inertial>
      <origin rpy="0 0 0" xyz="0.0 -0.018 -0.169"/>
      <mass value="1.03"/>
      <inertia ixx="0.018644469" ixy="-5.2e-08" ixz="1.0157e-05" iyy="0.019312599" iyz="-0.002520077" izz="0.002838361"/>
    </inertial>
  </link>
  <!-- [rad] -->
  <!-- joint thigh KFE -->
  <joint name="RF_thigh_fixed_RF_KFE" type="fixed">
    <parent link="RF_thigh_fixed"/>
    <child link="RF_KFE"/>
    <origin rpy="0 0 -1.5707963267948966" xyz="0.0 -0.1003 -0.285"/>
  </joint>
  <!-- [m] -->
  <!-- [A] -->
  <!-- Drive link -->
  <link name="RF_KFE">
    <visual>
      <origin rpy="0 0 0" xyz="0 0 0"/>
      <geometry>
        <mesh filename="package://anymal_c/urdf/leg/drives/drive_3_0_2_mesh.dae" scale="1.0 1.0     1.0"/>
      </geometry>
    </visual>
    <collision>
      <origin rpy="0 1.5707963267948966 0" xyz="-0.07 0 0"/>
      <geometry>
        <cylinder length="0.14" radius="0.05"/>
      </geometry>
    </collision>
    <inertial>
      <origin rpy="0 0 0" xyz="-0.063 7e-05 0.00046"/>
      <mass value="2.04"/>
      <inertia ixx="0.001053013" ixy="4.527e-05" ixz="8.855e-05" iyy="0.001805509" iyz="9.909e-05" izz="0.001765827"/>
    </inertial>
  </link>
  <!-- joint Drive output -->
  <joint name="RF_KFE" type="revolute">
    <parent link="RF_KFE"/>
    <child link="RF_SHANK"/>
    <origin rpy="0 0 0" xyz="0 0 0"/>
    <axis xyz="-1 0 0"/>
    <limit command_effort="80.0" current="32.0" effort="80.0" gear_velocity="7.5" lower="-9.42477796076938" upper="9.42477796076938" velocity="7.5"/>
    <dynamics damping="0.0" friction="0.0"/>
  </joint>
  <!-- Drive output link -->
  <link name="RF_SHANK">
    <inertial>
      <origin rpy="0 0 0" xyz="0 0 0"/>
      <mass value="0.001"/>
      <inertia ixx="0.000001" ixy="0.0" ixz="0.0" iyy="0.000001" iyz="0.0" izz="0.000001"/>
    </inertial>
  </link>
  <!-- [m] -->
  <!-- measured -->
  <!-- joint KFE shank -->
  <joint name="RF_shank_RF_shank_fixed" type="fixed">
    <parent link="RF_SHANK"/>
    <child link="RF_shank_fixed"/>
    <origin rpy="0 0 1.5707963267948966" xyz="0 0 0"/>
  </joint>
  <!-- Shank link -->
  <link name="RF_shank_fixed">
    <visual>
      <origin rpy="0 0 0.0" xyz="0 0 0"/>
      <geometry>
        <mesh filename="package://anymal_c/urdf/leg/shank/shank_3_1_1_mesh_mirrored.dae" scale="1.0 1.0     1.0"/>
      </geometry>
    </visual>
    <!-- Shank collision -->
    <collision>
      <origin rpy="1.5707963267948966 0 0" xyz="0 -0.02 0"/>
      <geometry>
        <cylinder length="0.04" radius="0.06"/>
      </geometry>
    </collision>
    <collision>
      <origin rpy="1.5707963267948966 0 0" xyz="0.057499 -0.02 0"/>
      <geometry>
        <box size="0.114998 0.0675 0.04"/>
      </geometry>
    </collision>
    <inertial>
      <origin rpy="0 0 0" xyz="0.03463 -0.00688 0.00098"/>
      <mass value="0.33742"/>
      <inertia ixx="0.00032748005" ixy="-2.142561e-05" ixz="1.33942e-05" iyy="0.00110974122" iyz="-7.601e-08" izz="0.00089388521"/>
    </inertial>
  </link>
  <!-- Leg configurations: xx (knees bent inwards), xo (knees bent backwards) -->
  <!-- joint shank foot -->
  <joint name="RF_shank_fixed_RF_FOOT" type="fixed">
    <parent link="RF_shank_fixed"/>
    <child link="RF_FOOT"/>
    <origin rpy="0 0 0" xyz="0.08795 -0.01305 -0.33797"/>
  </joint>
  <!-- Foot link -->
  <link name="RF_FOOT">
    <visual>
      <origin rpy="0 0 0.7853981633974483" xyz="0 0 0"/>
      <geometry>
        <mesh filename="package://anymal_c/urdf/leg/foot/foot_3_1_1_mesh.dae" scale="1.0 1.0     1.0"/>
      </geometry>
    </visual>
    <!-- Adapter collision -->
    <collision>
      <origin rpy="0 0 0" xyz="0 0 0.168985"/>
      <geometry>
        <cylinder length="0.282504" radius="0.0175"/>
      </geometry>
    </collision>
    <!-- Foot collision -->
    <collision>
      <origin xyz="0 0 0.0225"/>
      <geometry>
        <sphere radius="0.03"/>
      </geometry>
    </collision>
    <inertial>
      <origin rpy="0 0 0" xyz="0.00948 0.00948 0.1468"/>
      <mass value="0.25"/>
      <inertia ixx="0.00317174097" ixy="-2.63048e-06" ixz="6.815581e-05" iyy="0.00317174092" iyz="-6.815583e-05" izz="8.319196e-05"/>
    </inertial>
  </link>
  <!-- Gazebo customization -->
  <gazebo reference="RF_FOOT">
    <kp>1000000.0</kp>
    <kd>100.0</kd>
    <mu1>0.8</mu1>
    <mu2>0.8</mu2>
  </gazebo>
  <!-- [rad] -->
  <!-- [rad] -->
  <!-- joint base HAA -->
  <joint name="base_LH_HAA" type="fixed">
    <parent link="base"/>
    <child link="LH_HAA"/>
    <origin rpy="-2.6179938779914944 0 -3.141592653589793" xyz="-0.2999 0.104 0.0"/>
  </joint>
  <!-- [m] -->
  <!-- [A] -->
  <!-- Drive link -->
  <link name="LH_HAA">
    <visual>
      <origin rpy="0 0 0" xyz="0 0 0"/>
      <geometry>
        <mesh filename="package://anymal_c/urdf/leg/drives/drive_3_0_2_mesh.dae" scale="1.0 1.0     1.0"/>
      </geometry>
    </visual>
    <inertial>
      <origin rpy="0 0 0" xyz="-0.063 7e-05 0.00046"/>
      <mass value="2.04"/>
      <inertia ixx="0.001053013" ixy="4.527e-05" ixz="8.855e-05" iyy="0.001805509" iyz="9.909e-05" izz="0.001765827"/>
    </inertial>
  </link>
  <!-- joint Drive output -->
  <joint name="LH_HAA" type="revolute">
    <parent link="LH_HAA"/>
    <child link="LH_HIP"/>
    <origin rpy="0 0 0" xyz="0 0 0"/>
    <axis xyz="-1 0 0"/>
    <limit command_effort="80.0" current="32.0" effort="80.0" gear_velocity="7.5" lower="-0.72" upper="0.49" velocity="7.5"/>
    <dynamics damping="0.0" friction="0.0"/>
  </joint>
  <!-- Drive output link -->
  <link name="LH_HIP">
    <inertial>
      <origin rpy="0 0 0" xyz="0 0 0"/>
      <mass value="0.001"/>
      <inertia ixx="0.000001" ixy="0.0" ixz="0.0" iyy="0.000001" iyz="0.0" izz="0.000001"/>
    </inertial>
  </link>
  <!-- [kg * m^2] -->
  <!-- joint HAA hip -->
  <joint name="LH_HIP_LH_hip_fixed" type="fixed">
    <parent link="LH_HIP"/>
    <child link="LH_hip_fixed"/>
    <origin rpy="-2.6179938779914944 0 -3.141592653589793" xyz="0 0 0"/>
  </joint>
  <!-- Hip link -->
  <link name="LH_hip_fixed">
    <visual>
      <origin rpy="0 0 -3.141592653589793" xyz="0 0 0"/>
      <geometry>
        <mesh filename="package://anymal_c/urdf/leg/hip/hip_3_1_1_mesh_mirrored.dae" scale="1.0 1.0     1.0"/>
      </geometry>
    </visual>
    <inertial>
      <origin rpy="0 0 0" xyz="-0.048 0.008 -0.003"/>
      <mass value="0.74"/>
      <inertia ixx="0.001393106" ixy="-8.4012e-05" ixz="-2.3378e-05" iyy="0.003798579" iyz="7.1319e-05" izz="0.003897509"/>
    </inertial>
  </link>
  <!-- [rad] -->
  <!-- joint hip HFE -->
  <joint name="LH_hip_fixed_LH_HFE" type="fixed">
    <parent link="LH_hip_fixed"/>
    <child link="LH_HFE"/>
    <origin rpy="0 0 1.5707963267948966" xyz="-0.0599 0.08381 0.0"/>
  </joint>
  <!-- [m] -->
  <!-- [A] -->
  <!-- Drive link -->
  <link name="LH_HFE">
    <visual>
      <origin rpy="0 0 0" xyz="0 0 0"/>
      <geometry>
        <mesh filename="package://anymal_c/urdf/leg/drives/drive_3_0_2_mesh.dae" scale="1.0 1.0     1.0"/>
      </geometry>
    </visual>
    <collision>
      <origin rpy="0 1.5707963267948966 0" xyz="-0.07 0 0"/>
      <geometry>
        <cylinder length="0.14" radius="0.05"/>
      </geometry>
    </collision>
    <inertial>
      <origin rpy="0 0 0" xyz="-0.063 7e-05 0.00046"/>
      <mass value="2.04"/>
      <inertia ixx="0.001053013" ixy="4.527e-05" ixz="8.855e-05" iyy="0.001805509" iyz="9.909e-05" izz="0.001765827"/>
    </inertial>
  </link>
  <!-- joint Drive output -->
  <joint name="LH_HFE" type="revolute">
    <parent link="LH_HFE"/>
    <child link="LH_THIGH"/>
    <origin rpy="0 0 0" xyz="0 0 0"/>
    <axis xyz="1 0 0"/>
    <limit command_effort="80.0" current="32.0" effort="80.0" gear_velocity="7.5" lower="-9.42477796076938" upper="9.42477796076938" velocity="7.5"/>
    <dynamics damping="0.0" friction="0.0"/>
  </joint>
  <!-- Drive output link -->
  <link name="LH_THIGH">
    <inertial>
      <origin rpy="0 0 0" xyz="0 0 0"/>
      <mass value="0.001"/>
      <inertia ixx="0.000001" ixy="0.0" ixz="0.0" iyy="0.000001" iyz="0.0" izz="0.000001"/>
    </inertial>
  </link>
  <!-- [m] -->
  <!-- measured -->
  <!-- joint HFE thigh -->
  <joint name="LH_THIGH_LH_thigh_fixed" type="fixed">
    <parent link="LH_THIGH"/>
    <child link="LH_thigh_fixed"/>
    <origin rpy="0 0 -1.5707963267948966" xyz="0 0 0"/>
  </joint>
  <!-- Thigh link -->
  <link name="LH_thigh_fixed">
    <visual>
      <origin rpy="0 0 0.0" xyz="0 0 0"/>
      <geometry>
        <mesh filename="package://anymal_c/urdf/leg/thigh/thigh_3_1_1_mesh.dae" scale="1.0 1.0     1.0"/>
      </geometry>
    </visual>
    <!-- Thigh collision -->
    <collision>
      <origin rpy="1.5707963267948966 0 0" xyz="0 0.04 0"/>
      <geometry>
        <cylinder length="0.08" radius="0.065"/>
      </geometry>
    </collision>
    <collision>
      <origin rpy="0 0 0" xyz="0 0.03 -0.1413135"/>
      <geometry>
        <box size="0.07500000000000001 0.06 0.282627"/>
      </geometry>
    </collision>
    <inertial>
      <origin rpy="0 0 0" xyz="-0.0 0.018 -0.169"/>
      <mass value="1.03"/>
      <inertia ixx="0.018644469" ixy="-5.2e-08" ixz="-1.0157e-05" iyy="0.019312599" iyz="0.002520077" izz="0.002838361"/>
    </inertial>
  </link>
  <!-- [rad] -->
  <!-- joint thigh KFE -->
  <joint name="LH_thigh_fixed_LH_KFE" type="fixed">
    <parent link="LH_thigh_fixed"/>
    <child link="LH_KFE"/>
    <origin rpy="0 0 1.5707963267948966" xyz="-0.0 0.1003 -0.285"/>
  </joint>
  <!-- [m] -->
  <!-- [A] -->
  <!-- Drive link -->
  <link name="LH_KFE">
    <visual>
      <origin rpy="0 0 0" xyz="0 0 0"/>
      <geometry>
        <mesh filename="package://anymal_c/urdf/leg/drives/drive_3_0_2_mesh.dae" scale="1.0 1.0     1.0"/>
      </geometry>
    </visual>
    <collision>
      <origin rpy="0 1.5707963267948966 0" xyz="-0.07 0 0"/>
      <geometry>
        <cylinder length="0.14" radius="0.05"/>
      </geometry>
    </collision>
    <inertial>
      <origin rpy="0 0 0" xyz="-0.063 7e-05 0.00046"/>
      <mass value="2.04"/>
      <inertia ixx="0.001053013" ixy="4.527e-05" ixz="8.855e-05" iyy="0.001805509" iyz="9.909e-05" izz="0.001765827"/>
    </inertial>
  </link>
  <!-- joint Drive output -->
  <joint name="LH_KFE" type="revolute">
    <parent link="LH_KFE"/>
    <child link="LH_SHANK"/>
    <origin rpy="0 0 0" xyz="0 0 0"/>
    <axis xyz="1 0 0"/>
    <limit command_effort="80.0" current="32.0" effort="80.0" gear_velocity="7.5" lower="-9.42477796076938" upper="9.42477796076938" velocity="7.5"/>
    <dynamics damping="0.0" friction="0.0"/>
  </joint>
  <!-- Drive output link -->
  <link name="LH_SHANK">
    <inertial>
      <origin rpy="0 0 0" xyz="0 0 0"/>
      <mass value="0.001"/>
      <inertia ixx="0.000001" ixy="0.0" ixz="0.0" iyy="0.000001" iyz="0.0" izz="0.000001"/>
    </inertial>
  </link>
  <!-- [m] -->
  <!-- measured -->
  <!-- joint KFE shank -->
  <joint name="LH_shank_LH_shank_fixed" type="fixed">
    <parent link="LH_SHANK"/>
    <child link="LH_shank_fixed"/>
    <origin rpy="0 0 -1.5707963267948966" xyz="0 0 0"/>
  </joint>
  <!-- Shank link -->
  <link name="LH_shank_fixed">
    <visual>
      <origin rpy="0 0 -3.141592653589793" xyz="0 0 0"/>
      <geometry>
        <mesh filename="package://anymal_c/urdf/leg/shank/shank_3_1_1_mesh_mirrored.dae" scale="1.0 1.0     1.0"/>
      </geometry>
    </visual>
    <!-- Shank collision -->
    <collision>
      <origin rpy="1.5707963267948966 0 0" xyz="0 0.02 0"/>
      <geometry>
        <cylinder length="0.04" radius="0.06"/>
      </geometry>
    </collision>
    <collision>
      <origin rpy="1.5707963267948966 0 0" xyz="-0.057499 0.02 0"/>
      <geometry>
        <box size="0.114998 0.0675 0.04"/>
      </geometry>
    </collision>
    <inertial>
      <origin rpy="0 0 0" xyz="-0.03463 0.00688 0.00098"/>
      <mass value="0.33742"/>
      <inertia ixx="0.00032748005" ixy="-2.142561e-05" ixz="-1.33942e-05" iyy="0.00110974122" iyz="7.601e-08" izz="0.00089388521"/>
    </inertial>
  </link>
  <!-- Leg configurations: xx (knees bent inwards), xo (knees bent backwards) -->
  <!-- joint shank foot -->
  <joint name="LH_shank_fixed_LH_FOOT" type="fixed">
    <parent link="LH_shank_fixed"/>
    <child link="LH_FOOT"/>
    <origin rpy="0 0 0" xyz="-0.08795 0.01305 -0.33797"/>
  </joint>
  <!-- Foot link -->
  <link name="LH_FOOT">
    <visual>
      <origin rpy="0 0 -2.356194490192345" xyz="0 0 0"/>
      <geometry>
        <mesh filename="package://anymal_c/urdf/leg/foot/foot_3_1_1_mesh.dae" scale="1.0 1.0     1.0"/>
      </geometry>
    </visual>
    <!-- Adapter collision -->
    <collision>
      <origin rpy="0 0 0" xyz="0 0 0.168985"/>
      <geometry>
        <cylinder length="0.282504" radius="0.0175"/>
      </geometry>
    </collision>
    <!-- Foot collision -->
    <collision>
      <origin xyz="0 0 0.0225"/>
      <geometry>
        <sphere radius="0.03"/>
      </geometry>
    </collision>
    <inertial>
      <origin rpy="0 0 0" xyz="-0.00948 -0.00948 0.1468"/>
      <mass value="0.25"/>
      <inertia ixx="0.00317174097" ixy="-2.63048e-06" ixz="-6.815581e-05" iyy="0.00317174092" iyz="6.815583e-05" izz="8.319196e-05"/>
    </inertial>
  </link>
  <!-- Gazebo customization -->
  <gazebo reference="LH_FOOT">
    <kp>1000000.0</kp>
    <kd>100.0</kd>
    <mu1>0.8</mu1>
    <mu2>0.8</mu2>
  </gazebo>
  <!-- [rad] -->
  <!-- [rad] -->
  <!-- joint base HAA -->
  <joint name="base_RH_HAA" type="fixed">
    <parent link="base"/>
    <child link="RH_HAA"/>
    <origin rpy="2.6179938779914944 0 -3.141592653589793" xyz="-0.2999 -0.104 0.0"/>
  </joint>
  <!-- [m] -->
  <!-- [A] -->
  <!-- Drive link -->
  <link name="RH_HAA">
    <visual>
      <origin rpy="0 0 0" xyz="0 0 0"/>
      <geometry>
        <mesh filename="package://anymal_c/urdf/leg/drives/drive_3_0_2_mesh.dae" scale="1.0 1.0     1.0"/>
      </geometry>
    </visual>
    <inertial>
      <origin rpy="0 0 0" xyz="-0.063 7e-05 0.00046"/>
      <mass value="2.04"/>
      <inertia ixx="0.001053013" ixy="4.527e-05" ixz="8.855e-05" iyy="0.001805509" iyz="9.909e-05" izz="0.001765827"/>
    </inertial>
  </link>
  <!-- joint Drive output -->
  <joint name="RH_HAA" type="revolute">
    <parent link="RH_HAA"/>
    <child link="RH_HIP"/>
    <origin rpy="0 0 0" xyz="0 0 0"/>
    <axis xyz="-1 0 0"/>
    <limit command_effort="80.0" current="32.0" effort="80.0" gear_velocity="7.5" lower="-0.49" upper="0.72" velocity="7.5"/>
    <dynamics damping="0.0" friction="0.0"/>
  </joint>
  <!-- Drive output link -->
  <link name="RH_HIP">
    <inertial>
      <origin rpy="0 0 0" xyz="0 0 0"/>
      <mass value="0.001"/>
      <inertia ixx="0.000001" ixy="0.0" ixz="0.0" iyy="0.000001" iyz="0.0" izz="0.000001"/>
    </inertial>
  </link>
  <!-- [kg * m^2] -->
  <!-- joint HAA hip -->
  <joint name="RH_HIP_RH_hip_fixed" type="fixed">
    <parent link="RH_HIP"/>
    <child link="RH_hip_fixed"/>
    <origin rpy="2.6179938779914944 0 -3.141592653589793" xyz="0 0 0"/>
  </joint>
  <!-- Hip link -->
  <link name="RH_hip_fixed">
    <visual>
      <origin rpy="0 0 -3.141592653589793" xyz="0 0 0"/>
      <geometry>
        <mesh filename="package://anymal_c/urdf/leg/hip/hip_3_1_1_mesh.dae" scale="1.0 1.0     1.0"/>
      </geometry>
    </visual>
    <inertial>
      <origin rpy="0 0 0" xyz="-0.048 -0.008 -0.003"/>
      <mass value="0.74"/>
      <inertia ixx="0.001393106" ixy="8.4012e-05" ixz="-2.3378e-05" iyy="0.003798579" iyz="-7.1319e-05" izz="0.003897509"/>
    </inertial>
  </link>
  <!-- [rad] -->
  <!-- joint hip HFE -->
  <joint name="RH_hip_fixed_RH_HFE" type="fixed">
    <parent link="RH_hip_fixed"/>
    <child link="RH_HFE"/>
    <origin rpy="0 0 -1.5707963267948966" xyz="-0.0599 -0.08381 0.0"/>
  </joint>
  <!-- [m] -->
  <!-- [A] -->
  <!-- Drive link -->
  <link name="RH_HFE">
    <visual>
      <origin rpy="0 0 0" xyz="0 0 0"/>
      <geometry>
        <mesh filename="package://anymal_c/urdf/leg/drives/drive_3_0_2_mesh.dae" scale="1.0 1.0     1.0"/>
      </geometry>
    </visual>
    <collision>
      <origin rpy="0 1.5707963267948966 0" xyz="-0.07 0 0"/>
      <geometry>
        <cylinder length="0.14" radius="0.05"/>
      </geometry>
    </collision>
    <inertial>
      <origin rpy="0 0 0" xyz="-0.063 7e-05 0.00046"/>
      <mass value="2.04"/>
      <inertia ixx="0.001053013" ixy="4.527e-05" ixz="8.855e-05" iyy="0.001805509" iyz="9.909e-05" izz="0.001765827"/>
    </inertial>
  </link>
  <!-- joint Drive output -->
  <joint name="RH_HFE" type="revolute">
    <parent link="RH_HFE"/>
    <child link="RH_THIGH"/>
    <origin rpy="0 0 0" xyz="0 0 0"/>
    <axis xyz="-1 0 0"/>
    <limit command_effort="80.0" current="32.0" effort="80.0" gear_velocity="7.5" lower="-9.42477796076938" upper="9.42477796076938" velocity="7.5"/>
    <dynamics damping="0.0" friction="0.0"/>
  </joint>
  <!-- Drive output link -->
  <link name="RH_THIGH">
    <inertial>
      <origin rpy="0 0 0" xyz="0 0 0"/>
      <mass value="0.001"/>
      <inertia ixx="0.000001" ixy="0.0" ixz="0.0" iyy="0.000001" iyz="0.0" izz="0.000001"/>
    </inertial>
  </link>
  <!-- [m] -->
  <!-- measured -->
  <!-- joint HFE thigh -->
  <joint name="RH_THIGH_RH_thigh_fixed" type="fixed">
    <parent link="RH_THIGH"/>
    <child link="RH_thigh_fixed"/>
    <origin rpy="0 0 1.5707963267948966" xyz="0 0 0"/>
  </joint>
  <!-- Thigh link -->
  <link name="RH_thigh_fixed">
    <visual>
      <origin rpy="0 0 -3.141592653589793" xyz="0 0 0"/>
      <geometry>
        <mesh filename="package://anymal_c/urdf/leg/thigh/thigh_3_1_1_mesh.dae" scale="1.0 1.0     1.0"/>
      </geometry>
    </visual>
    <!-- Thigh collision -->
    <collision>
      <origin rpy="1.5707963267948966 0 0" xyz="0 -0.04 0"/>
      <geometry>
        <cylinder length="0.08" radius="0.065"/>
      </geometry>
    </collision>
    <collision>
      <origin rpy="0 0 0" xyz="0 -0.03 -0.1413135"/>
      <geometry>
        <box size="0.07500000000000001 0.06 0.282627"/>
      </geometry>
    </collision>
    <inertial>
      <origin rpy="0 0 0" xyz="-0.0 -0.018 -0.169"/>
      <mass value="1.03"/>
      <inertia ixx="0.018644469" ixy="5.2e-08" ixz="-1.0157e-05" iyy="0.019312599" iyz="-0.002520077" izz="0.002838361"/>
    </inertial>
  </link>
  <!-- [rad] -->
  <!-- joint thigh KFE -->
  <joint name="RH_thigh_fixed_RH_KFE" type="fixed">
    <parent link="RH_thigh_fixed"/>
    <child link="RH_KFE"/>
    <origin rpy="0 0 -1.5707963267948966" xyz="-0.0 -0.1003 -0.285"/>
  </joint>
  <!-- [m] -->
  <!-- [A] -->
  <!-- Drive link -->
  <link name="RH_KFE">
    <visual>
      <origin rpy="0 0 0" xyz="0 0 0"/>
      <geometry>
        <mesh filename="package://anymal_c/urdf/leg/drives/drive_3_0_2_mesh.dae" scale="1.0 1.0     1.0"/>
      </geometry>
    </visual>
    <collision>
      <origin rpy="0 1.5707963267948966 0" xyz="-0.07 0 0"/>
      <geometry>
        <cylinder length="0.14" radius="0.05"/>
      </geometry>
    </collision>
    <inertial>
      <origin rpy="0 0 0" xyz="-0.063 7e-05 0.00046"/>
      <mass value="2.04"/>
      <inertia ixx="0.001053013" ixy="4.527e-05" ixz="8.855e-05" iyy="0.001805509" iyz="9.909e-05" izz="0.001765827"/>
    </inertial>
  </link>
  <!-- joint Drive output -->
  <joint name="RH_KFE" type="revolute">
    <parent link="RH_KFE"/>
    <child link="RH_SHANK"/>
    <origin rpy="0 0 0" xyz="0 0 0"/>
    <axis xyz="-1 0 0"/>
    <limit command_effort="80.0" current="32.0" effort="80.0" gear_velocity="7.5" lower="-9.42477796076938" upper="9.42477796076938" velocity="7.5"/>
    <dynamics damping="0.0" friction="0.0"/>
  </joint>
  <!-- Drive output link -->
  <link name="RH_SHANK">
    <inertial>
      <origin rpy="0 0 0" xyz="0 0 0"/>
      <mass value="0.001"/>
      <inertia ixx="0.000001" ixy="0.0" ixz="0.0" iyy="0.000001" iyz="0.0" izz="0.000001"/>
    </inertial>
  </link>
  <!-- [m] -->
  <!-- measured -->
  <!-- joint KFE shank -->
  <joint name="RH_shank_RH_shank_fixed" type="fixed">
    <parent link="RH_SHANK"/>
    <child link="RH_shank_fixed"/>
    <origin rpy="0 0 1.5707963267948966" xyz="0 0 0"/>
  </joint>
  <!-- Shank link -->
  <link name="RH_shank_fixed">
    <visual>
      <origin rpy="0 0 -3.141592653589793" xyz="0 0 0"/>
      <geometry>
        <mesh filename="package://anymal_c/urdf/leg/shank/shank_3_1_1_mesh.dae" scale="1.0 1.0     1.0"/>
      </geometry>
    </visual>
    <!-- Shank collision -->
    <collision>
      <origin rpy="1.5707963267948966 0 0" xyz="0 -0.02 0"/>
      <geometry>
        <cylinder length="0.04" radius="0.06"/>
      </geometry>
    </collision>
    <collision>
      <origin rpy="1.5707963267948966 0 0" xyz="-0.057499 -0.02 0"/>
      <geometry>
        <box size="0.114998 0.0675 0.04"/>
      </geometry>
    </collision>
    <inertial>
      <origin rpy="0 0 0" xyz="-0.03463 -0.00688 0.00098"/>
      <mass value="0.33742"/>
      <inertia ixx="0.00032748005" ixy="2.142561e-05" ixz="-1.33942e-05" iyy="0.00110974122" iyz="-7.601e-08" izz="0.00089388521"/>
    </inertial>
  </link>
  <!-- Leg configurations: xx (knees bent inwards), xo (knees bent backwards) -->
  <!-- joint shank foot -->
  <joint name="RH_shank_fixed_RH_FOOT" type="fixed">
    <parent link="RH_shank_fixed"/>
    <child link="RH_FOOT"/>
    <origin rpy="0 0 0" xyz="-0.08795 -0.01305 -0.33797"/>
  </joint>
  <!-- Foot link -->
  <link name="RH_FOOT">
    <visual>
      <origin rpy="0 0 -3.9269908169872414" xyz="0 0 0"/>
      <geometry>
        <mesh filename="package://anymal_c/urdf/leg/foot/foot_3_1_1_mesh.dae" scale="1.0 1.0     1.0"/>
      </geometry>
    </visual>
    <!-- Adapter collision -->
    <collision>
      <origin rpy="0 0 0" xyz="0 0 0.168985"/>
      <geometry>
        <cylinder length="0.282504" radius="0.0175"/>
      </geometry>
    </collision>
    <!-- Foot collision -->
    <collision>
      <origin xyz="0 0 0.0225"/>
      <geometry>
        <sphere radius="0.03"/>
      </geometry>
    </collision>
    <inertial>
      <origin rpy="0 0 0" xyz="-0.00948 0.00948 0.1468"/>
      <mass value="0.25"/>
      <inertia ixx="0.00317174097" ixy="2.63048e-06" ixz="-6.815581e-05" iyy="0.00317174092" iyz="-6.815583e-05" izz="8.319196e-05"/>
    </inertial>
  </link>
  <!-- Gazebo customization -->
  <gazebo reference="RH_FOOT">
    <kp>1000000.0</kp>
    <kd>100.0</kd>
    <mu1>0.8</mu1>
    <mu2>0.8</mu2>
  </gazebo>
  <!--
    The following transforms are approximate and require further calibration.
    
    We will replace these with properly aligned transforms once we have them.
    -->
  <gazebo reference="hatch_top">
    <mu1>0.2</mu1>
    <mu2>0.2</mu2>
    <material>Gazebo/DarkGrey</material>
  </gazebo>
  <gazebo reference="hatch_unitree_support">
    <mu1>0.2</mu1>
    <mu2>0.2</mu2>
    <material>Gazebo/Grey</material>
  </gazebo>
  <material name="light_grey">
    <color rgba="0.6 0.6 0.6 1.0"/>
  </material>
  <material name="dark_grey">
    <color rgba="0.1 0.1 0.1 1.0"/>
  </material>
  <joint name="hatch_to_hatch_top" type="fixed">
    <parent link="hatch"/>
    <child link="hatch_top"/>
    <origin rpy="0.0 0.0 0.0" xyz="0.0 0.0 0.015"/>
  </joint>
  <link name="hatch_top">
    <collision>
      <origin rpy="0 0 0" xyz="0 0 0"/>
      <geometry>
        <box size="0.1495 0.108 0.02"/>
      </geometry>
    </collision>
    <visual>
      <origin rpy="0 0 0" xyz="0 0 0"/>
      <geometry>
        <box size="0.1495 0.108 0.02"/>
      </geometry>
      <material name="dark_grey"/>
    </visual>
    <inertial>
      <origin rpy="0 0 0" xyz="0 0 0"/>
      <mass value="0.1"/>
      <inertia ixx="0.00010053333333333331" ixy="0.0" ixz="0.0" iyy="0.00018958541666666667" iyz="0.0" izz="0.0002834520833333333"/>
    </inertial>
  </link>
  <joint name="hatch_top_to_hatch_unitree_support" type="fixed">
    <parent link="hatch_top"/>
    <child link="hatch_unitree_support"/>
    <origin rpy="0.0 0.0 0.0" xyz="0.02525 0.0 0.015"/>
  </joint>
  <link name="hatch_unitree_support">
    <collision>
      <origin rpy="0 0 0" xyz="0 0 0"/>
      <geometry>
        <box size="0.098 0.19 0.01"/>
      </geometry>
    </collision>
    <visual>
      <origin rpy="0 0 0" xyz="0 0 0"/>
      <geometry>
        <box size="0.098 0.19 0.01"/>
      </geometry>
      <material name="light_grey"/>
    </visual>
    <inertial>
      <origin rpy="0 0 0" xyz="0 0 0"/>
      <mass value="0.5"/>
      <inertia ixx="0.0015083333333333333" ixy="0.0" ixz="0.0" iyy="0.00040433333333333337" iyz="0.0" izz="0.0019043333333333334"/>
    </inertial>
  </link>
  <joint name="hatch_unitree_support_to_unitree_mount" type="fixed">
    <parent link="hatch_unitree_support"/>
    <child link="unitree_mount"/>
    <origin rpy="0 0 0" xyz="0 0 0.005"/>
  </joint>
  <link name="unitree_mount"/>
  <!-- Link 06 -->
  <!-- <xacro:property name="L06_Mass" value="0.28875807"/>
    <xacro:property name="L06_ComX" value="0.02415690"/>
    <xacro:property name="L06_ComY" value="-0.00017355"/>
    <xacro:property name="L06_ComZ" value="-0.00143876"/>
    <xacro:property name="L06_Ixx" value="0.00018328"/>
    <xacro:property name="L06_Ixy" value="0.00000122"/>
    <xacro:property name="L06_Ixz" value="0.00000054"/>
    <xacro:property name="L06_Iyy" value="0.00014750"/>
    <xacro:property name="L06_Iyz" value="0.00000008"/>
    <xacro:property name="L06_Izz" value="0.00014680"/> -->
  <!-- Link Gripper Stator -->
  <!-- <xacro:property name="GripperStator_Mass" value="0.52603655"/>
    <xacro:property name="GripperStator_ComX" value="0.04764427"/>
    <xacro:property name="GripperStator_ComY" value="-0.00035819"/>
    <xacro:property name="GripperStator_ComZ" value="-0.00249162"/>
    <xacro:property name="GripperStator_Ixx" value="0.00038683"/>
    <xacro:property name="GripperStator_Ixy" value="-0.00000359"/>
    <xacro:property name="GripperStator_Ixz" value="0.00007662"/>
    <xacro:property name="GripperStator_Iyy" value="0.00068614"/>
    <xacro:property name="GripperStator_Iyz" value="0.00000209"/>
    <xacro:property name="GripperStator_Izz" value="0.00066293"/> -->
  <!-- Link Gripper Mover -->
  <!-- <xacro:property name="GripperMover_Mass" value="0.27621302"/>
    <xacro:property name="GripperMover_ComX" value="0.01320633"/>
    <xacro:property name="GripperMover_ComY" value="0.00476708"/>
    <xacro:property name="GripperMover_ComZ" value="0.00380534"/>
    <xacro:property name="GripperMover_Ixx" value="0.00017716"/>
    <xacro:property name="GripperMover_Ixy" value="0.00001683"/>
    <xacro:property name="GripperMover_Ixz" value="-0.00001786"/>
    <xacro:property name="GripperMover_Iyy" value="0.00026787"/>
    <xacro:property name="GripperMover_Iyz" value="0.00000262"/>
    <xacro:property name="GripperMover_Izz" value="0.00035728"/> -->
  <gazebo>
    <plugin filename="libgazebo_ros_control.so" name="gazebo_ros_control">
      <robotNamespace>/z1_gazebo</robotNamespace>
      <robotSimType>gazebo_ros_control/DefaultRobotHWSim</robotSimType>
    </plugin>
  </gazebo>
  <!-- Uncommenting these for links 0-4 causes the sim to fail -->
  <!-- <gazebo reference="link00">
        <self_collide>true</self_collide>
    </gazebo>

    <gazebo reference="link01">
        <self_collide>true</self_collide>
    </gazebo>

    <gazebo reference="link02">
        <self_collide>true</self_collide>
    </gazebo>

    <gazebo reference="link03">
        <self_collide>true</self_collide>
    </gazebo> -->
  <gazebo reference="link04">
    <self_collide>true</self_collide>
  </gazebo>
  <gazebo reference="link05">
    <self_collide>true</self_collide>
  </gazebo>
  <gazebo reference="link06">
    <self_collide>false</self_collide>
  </gazebo>
  <joint name="base_static_joint" type="fixed">
    <origin rpy="0 0 0" xyz="0 0 0"/>
    <parent link="unitree_mount"/>
    <child link="link00"/>
  </joint>
  <link name="link00">
    <visual>
      <origin rpy="0 0 0" xyz="0 0 0"/>
      <geometry>
        <mesh filename="package://z1_description/meshes/visual/z1_Link00.dae" scale="1 1 1"/>
      </geometry>
    </visual>
    <collision>
      <geometry>
        <cylinder length="0.051" radius="0.0325"/>
      </geometry>
      <origin rpy="0 0 0" xyz="0 0 0.0255"/>
    </collision>
    <inertial>
      <origin rpy="0 0 0" xyz="-0.00334984 -0.00013615 0.02495843"/>
      <mass value="0.47247481"/>
      <inertia ixx="0.00037937" ixy="-3.5e-07" ixz="-1.037e-05" iyy="0.00041521" iyz="-9.9e-07" izz="0.00053066"/>
    </inertial>
  </link>
  <joint name="joint1" type="revolute">
    <origin rpy="0 0 0" xyz="0 0 0.0585"/>
    <parent link="link00"/>
    <child link="link01"/>
    <axis xyz="0 0 1"/>
    <dynamics damping="1.0" friction="1.0"/>
    <limit effort="30.0" lower="-2.6179938779914944" upper="2.6179938779914944" velocity="3.1415"/>
  </joint>
  <link name="link01">
    <visual>
      <origin rpy="0 0 0" xyz="0 0 0"/>
      <geometry>
        <mesh filename="package://z1_description/meshes/visual/z1_Link01.dae" scale="1 1 1"/>
      </geometry>
    </visual>
    <inertial>
      <origin rpy="0 0 0" xyz="2.47e-06 -0.00025198 0.02317169"/>
      <mass value="0.67332551"/>
      <inertia ixx="0.00128328" ixy="-6e-08" ixz="-4e-07" iyy="0.00071931" iyz="5e-07" izz="0.00083936"/>
    </inertial>
  </link>
  <joint name="joint2" type="revolute">
    <origin rpy="0 0 0" xyz="0 0 0.045"/>
    <parent link="link01"/>
    <child link="link02"/>
    <axis xyz="0 1 0"/>
    <dynamics damping="2.0" friction="2.0"/>
    <limit effort="60.0" lower="0.0" upper="2.9670597283903604" velocity="3.1415"/>
  </joint>
  <link name="link02">
    <visual>
      <origin rpy="0 0 0" xyz="0 0 0"/>
      <geometry>
        <mesh filename="package://z1_description/meshes/visual/z1_Link02.dae" scale="1 1 1"/>
      </geometry>
    </visual>
    <collision>
      <geometry>
        <cylinder length="0.102" radius="0.0325"/>
      </geometry>
      <origin rpy="1.5707963267948966 0 0" xyz="0 0 0"/>
    </collision>
    <collision>
      <geometry>
        <cylinder length="0.235" radius="0.0225"/>
      </geometry>
      <origin rpy="0 1.5707963267948966 0" xyz="-0.16249999999999998 0 0"/>
    </collision>
    <collision>
      <geometry>
        <cylinder length="0.051" radius="0.0325"/>
      </geometry>
      <origin rpy="1.5707963267948966 0 0" xyz="-0.35 0 0"/>
    </collision>
    <inertial>
      <origin rpy="0 0 0" xyz="-0.11012601 0.00240029 0.00158266"/>
      <mass value="1.19132258"/>
      <inertia ixx="0.00102138" ixy="0.00062358" ixz="5.13e-06" iyy="0.02429457" iyz="-2.1e-06" izz="0.02466114"/>
    </inertial>
  </link>
  <joint name="joint3" type="revolute">
    <origin rpy="0 0 0" xyz="-0.35 0 0"/>
    <parent link="link02"/>
    <child link="link03"/>
    <axis xyz="0 1 0"/>
    <dynamics damping="1.0" friction="1.0"/>
    <limit effort="30.0" lower="-2.8797932657906435" upper="0.0" velocity="3.1415"/>
  </joint>
  <link name="link03">
    <visual>
      <origin rpy="0 0 0" xyz="0 0 0"/>
      <geometry>
        <mesh filename="package://z1_description/meshes/visual/z1_Link03.dae" scale="1 1 1"/>
      </geometry>
    </visual>
    <collision>
      <geometry>
        <cylinder length="0.116" radius="0.02"/>
      </geometry>
      <origin rpy="0 1.5707963267948966 0" xyz="0.128 0 0.055"/>
    </collision>
    <collision>
      <geometry>
        <cylinder length="0.059" radius="0.0325"/>
      </geometry>
      <origin rpy="0 1.5707963267948966 1.5707963267948966" xyz="0.2205 0 0.055"/>
    </collision>
    <inertial>
      <origin rpy="0 0 0" xyz="0.10609208 -0.00541815 0.03476383"/>
      <mass value="0.83940874"/>
      <inertia ixx="0.00108061" ixy="-8.669e-05" ixz="-0.00208102" iyy="0.00954238" iyz="-1.332e-05" izz="0.00886621"/>
    </inertial>
  </link>
  <joint name="joint4" type="revolute">
    <origin rpy="0 0 0" xyz="0.218 0 0.057"/>
    <parent link="link03"/>
    <child link="link04"/>
    <axis xyz="0 1 0"/>
    <dynamics damping="1.0" friction="1.0"/>
    <limit effort="30.0" lower="-1.5184364492350666" upper="1.5184364492350666" velocity="3.1415"/>
  </joint>
  <link name="link04">
    <visual>
      <origin rpy="0 0 0" xyz="0 0 0"/>
      <geometry>
        <mesh filename="package://z1_description/meshes/visual/z1_Link04.dae" scale="1 1 1"/>
      </geometry>
    </visual>
    <collision>
      <geometry>
        <cylinder length="0.067" radius="0.0325"/>
      </geometry>
      <origin rpy="0 0 0" xyz="0.072 0 0"/>
    </collision>
    <inertial>
      <origin rpy="0 0 0" xyz="0.04366681 0.00364738 -0.00170192"/>
      <mass value="0.56404563"/>
      <inertia ixx="0.00031576" ixy="8.13e-05" ixz="4.091e-05" iyy="0.00092996" iyz="-5.96e-06" izz="0.00097912"/>
    </inertial>
  </link>
  <joint name="joint5" type="revolute">
    <origin rpy="0 0 0" xyz="0.07 0.0 0.0"/>
    <parent link="link04"/>
    <child link="link05"/>
    <axis xyz="0 0 1"/>
    <dynamics damping="1.0" friction="1.0"/>
    <limit effort="30.0" lower="-1.3439035240356338" upper="1.3439035240356338" velocity="3.1415"/>
  </joint>
  <link name="link05">
    <visual>
      <origin rpy="0 0 0" xyz="0 0 0"/>
      <geometry>
        <mesh filename="package://z1_description/meshes/visual/z1_Link05.dae" scale="1 1 1"/>
      </geometry>
    </visual>
    <inertial>
      <origin rpy="0 0 0" xyz="0.03121533 0.0 0.00646316"/>
      <mass value="0.38938492"/>
      <inertia ixx="0.00017605" ixy="4e-07" ixz="5.689e-05" iyy="0.00055896" iyz="-1.3e-07" izz="0.0005386"/>
    </inertial>
  </link>
  <joint name="joint6" type="revolute">
    <origin rpy="0 0 0" xyz="0.0492 0.0 0.0"/>
    <parent link="link05"/>
    <child link="link06"/>
    <axis xyz="1 0 0"/>
    <dynamics damping="1.0" friction="1.0"/>
    <limit effort="30.0" lower="-2.792526803190927" upper="2.792526803190927" velocity="3.1415"/>
  </joint>
  <link name="link06">
    <visual>
      <origin rpy="0 0 0" xyz="0 0 0"/>
      <geometry>
        <mesh filename="package://z1_description/meshes/visual/z1_Link06.dae" scale="1 1 1"/>
      </geometry>
    </visual>
    <collision>
      <geometry>
        <cylinder length="0.051" radius="0.0325"/>
      </geometry>
      <origin rpy="0 1.5707963267948966 0" xyz="0.0255 0 0"/>
    </collision>
    <inertial>
      <origin rpy="0 0 0" xyz="0.0241569 -0.00017355 -0.00143876"/>
      <mass value="0.28875807"/>
      <inertia ixx="0.0009" ixy="6e-06" ixz="2.7e-06" iyy="0.00075" iyz="4e-07" izz="0.00075"/>
    </inertial>
  </link>
  <joint name="gripperStator" type="fixed">
    <origin rpy="0 0 0" xyz="0.051 0.0 0.0"/>
    <parent link="link06"/>
    <child link="gripperStator"/>
  </joint>
  <link name="gripperStator">
    <visual>
      <geometry>
        <mesh filename="package://z1_description/meshes/visual/z1_GripperStator.dae" scale="1 1 1"/>
      </geometry>
    </visual>
    <collision>
      <geometry>
        <mesh filename="package://z1_description/meshes/collision/z1_GripperStator.STL" scale="1 1 1"/>
      </geometry>
    </collision>
    <inertial>
      <origin rpy="0 0 0" xyz="0.04764427 -0.00035819 -0.00249162"/>
      <mass value="0.52603655"/>
      <inertia ixx="0.0038683" ixy="-3.59e-05" ixz="0.0007662" iyy="0.0068614" iyz="2.09e-05" izz="0.0066293"/>
    </inertial>
  </link>
  <joint name="jointGripper" type="revolute">
    <origin rpy="0 0 0" xyz="0.049 0.0 0"/>
    <parent link="gripperStator"/>
    <child link="gripperMover"/>
    <axis xyz="0 1 0"/>
    <dynamics damping="1.0" friction="1.0"/>
    <limit effort="30.0" lower="-1.5707963267948966" upper="0.0" velocity="3.1415"/>
  </joint>
  <link name="gripperMover">
    <visual>
      <geometry>
        <mesh filename="package://z1_description/meshes/visual/z1_GripperMover.dae" scale="1 1 1"/>
      </geometry>
    </visual>
    <collision>
      <geometry>
        <mesh filename="package://z1_description/meshes/collision/z1_GripperMover.STL" scale="1 1 1"/>
      </geometry>
    </collision>
    <inertial>
      <origin rpy="0 0 0" xyz="0.01320633 0.00476708 0.00380534"/>
      <mass value="0.27621302"/>
      <inertia ixx="0.0017716" ixy="0.0001683" ixz="-0.0001786" iyy="0.0026787" iyz="2.62e-05" izz="0.0035728"/>
    </inertial>
  </link>
  <transmission name="JointTransGripper">
    <type>transmission_interface/SimpleTransmission</type>
    <joint name="jointGripper">
      <hardwareInterface>hardware_interface/EffortJointInterface</hardwareInterface>
    </joint>
    <actuator name="ActuatorGripper">
      <hardwareInterface>hardware_interface/EffortJointInterface</hardwareInterface>
      <mechanicalReduction>1</mechanicalReduction>
    </actuator>
  </transmission>
  <gazebo reference="gripperStator">
    <self_collide>false</self_collide>
  </gazebo>
  <gazebo reference="gripperMover">
    <self_collide>false</self_collide>
  </gazebo>
  <!--
    The following transforms are approximate and require further calibration.
    
    We will replace these with properly aligned transforms once we have them.
    -->
  <!-- unitree -->
  <joint name="hand_to_unitree_realsense_mount_joint" type="fixed">
    <origin rpy="0.0 0.0 0.0" xyz="0.0365 0.0 0.0"/>
    <!-- this needs tuning! -->
    <parent link="link06"/>
    <child link="unitree_realsense_mount"/>
  </joint>
  <link name="unitree_realsense_mount">
    <visual>
      <origin rpy="-1.5708 0.0 3.1416" xyz="0.0 0.0 0.0"/>
      <!-- rotate model to match unitree TF convention -->
      <geometry>
        <mesh filename="package://anymal_coyote_drs/urdf/modules/unitree_z1/unitree-realsense-mount.dae"/>
      </geometry>
    </visual>
  </link>
  <material name="aluminum">
    <color rgba="0.5 0.5 0.5 1"/>
  </material>
  <material name="plastic">
    <color rgba="0.1 0.1 0.1 1"/>
  </material>
  <!-- camera body, with origin at bottom screw mount -->
  <joint name="camera_joint" type="fixed">
    <origin rpy="0.0 0.0 0.0" xyz="0.008 0.0 0.0375"/>
    <parent link="unitree_realsense_mount"/>
    <child link="camera_bottom_screw_frame"/>
  </joint>
  <link name="camera_bottom_screw_frame"/>
  <joint name="camera_link_joint" type="fixed">
    <origin rpy="0 0 0" xyz="0.010600000000000002 0.0175 0.0125"/>
    <parent link="camera_bottom_screw_frame"/>
    <child link="camera_link"/>
  </joint>
  <link name="camera_link">
    <visual>
      <!-- the mesh origin is at front plate in between the two infrared camera axes -->
      <origin rpy="1.5707963267948966 0 1.5707963267948966" xyz="0.0043 -0.0175 0"/>
      <geometry>
        <mesh filename="package://realsense2_description/meshes/d435.dae"/>
      </geometry>
    </visual>
    <collision>
      <origin rpy="0 0 0" xyz="0 -0.0175 0"/>
      <geometry>
        <box size="0.02505 0.09 0.025"/>
      </geometry>
    </collision>
    <inertial>
      <!-- The following are not reliable values, and should not be used for modeling -->
      <mass value="0.072"/>
      <origin xyz="0 0 0"/>
      <inertia ixx="0.003881243" ixy="0.0" ixz="0.0" iyy="0.000498940" iyz="0.0" izz="0.003879257"/>
    </inertial>
  </link>
  <!-- camera depth joints and links -->
  <joint name="camera_depth_joint" type="fixed">
    <origin rpy="0 0 0" xyz="0 0 0"/>
    <parent link="camera_link"/>
    <child link="camera_depth_frame"/>
  </joint>
  <link name="camera_depth_frame"/>
  <joint name="camera_depth_optical_joint" type="fixed">
    <origin rpy="-1.5707963267948966 0 -1.5707963267948966" xyz="0 0 0"/>
    <parent link="camera_depth_frame"/>
    <child link="camera_depth_optical_frame"/>
  </joint>
  <link name="camera_depth_optical_frame"/>
  <!-- camera left IR joints and links -->
  <joint name="camera_infra1_joint" type="fixed">
    <origin rpy="0 0 0" xyz="0 0.0 0"/>
    <parent link="camera_link"/>
    <child link="camera_infra1_frame"/>
  </joint>
  <link name="camera_infra1_frame"/>
  <joint name="camera_infra1_optical_joint" type="fixed">
    <origin rpy="-1.5707963267948966 0 -1.5707963267948966" xyz="0 0 0"/>
    <parent link="camera_infra1_frame"/>
    <child link="camera_infra1_optical_frame"/>
  </joint>
  <link name="camera_infra1_optical_frame"/>
  <!-- camera right IR joints and links -->
  <joint name="camera_infra2_joint" type="fixed">
    <origin rpy="0 0 0" xyz="0 -0.05 0"/>
    <parent link="camera_link"/>
    <child link="camera_infra2_frame"/>
  </joint>
  <link name="camera_infra2_frame"/>
  <joint name="camera_infra2_optical_joint" type="fixed">
    <origin rpy="-1.5707963267948966 0 -1.5707963267948966" xyz="0 0 0"/>
    <parent link="camera_infra2_frame"/>
    <child link="camera_infra2_optical_frame"/>
  </joint>
  <link name="camera_infra2_optical_frame"/>
  <!-- camera color joints and links -->
  <joint name="camera_color_joint" type="fixed">
    <origin rpy="0 0 0" xyz="0 0.015 0"/>
    <parent link="camera_link"/>
    <child link="camera_color_frame"/>
  </joint>
  <link name="camera_color_frame"/>
  <joint name="camera_color_optical_joint" type="fixed">
    <origin rpy="-1.5707963267948966 0 -1.5707963267948966" xyz="0 0 0"/>
    <parent link="camera_color_frame"/>
    <child link="camera_color_optical_frame"/>
  </joint>
  <link name="camera_color_optical_frame"/>
  <link name="camera_accel_frame"/>
  <link name="camera_accel_optical_frame"/>
  <link name="camera_gyro_frame"/>
  <link name="camera_gyro_optical_frame"/>
  <joint name="camera_accel_joint" type="fixed">
    <origin rpy="0 0 0" xyz="-0.01174 -0.00552 0.0051"/>
    <parent link="camera_link"/>
    <child link="camera_accel_frame"/>
  </joint>
  <joint name="camera_accel_optical_joint" type="fixed">
    <origin rpy="-1.5707963267948966 0 -1.5707963267948966" xyz="0 0 0"/>
    <parent link="camera_accel_frame"/>
    <child link="camera_accel_optical_frame"/>
  </joint>
  <joint name="camera_gyro_joint" type="fixed">
    <origin rpy="0 0 0" xyz="-0.01174 -0.00552 0.0051"/>
    <parent link="camera_link"/>
    <child link="camera_gyro_frame"/>
  </joint>
  <joint name="camera_gyro_optical_joint" type="fixed">
    <origin rpy="-1.5707963267948966 0 -1.5707963267948966" xyz="0 0 0"/>
    <parent link="camera_gyro_frame"/>
    <child link="camera_gyro_optical_frame"/>
  </joint>
  <!-- xacro macro-->
  <!-- Gazebo plugin -->
  <!-- Depth sensor -->
  <gazebo reference="camera_depth_frame">
    <sensor name="camera_depth" type="depth">
      <always_on>1</always_on>
      <visualize>true</visualize>
      <update_rate>15.0</update_rate>
      <camera>
        <horizontal_fov>1.50098</horizontal_fov>
        <!-- 86 degrees -->
        <image>
          <width>848</width>
          <height>480</height>
          <format>R8G8B8</format>
        </image>
        <depth_camera>

          </depth_camera>
        <clip>
          <near>0.1</near>
          <far>10.0</far>
        </clip>
      </camera>
      <plugin filename="libgazebo_ros_openni_kinect.so" name="camera_controller">
        <alwaysOn>true</alwaysOn>
        <updateRate>0.0</updateRate>
        <cameraName>camera</cameraName>
        <frameName>camera_depth_optical_frame</frameName>
        <imageTopicName>color/image_raw</imageTopicName>
        <depthImageTopicName>aligned_depth_to_color/image_raw</depthImageTopicName>
        <pointCloudTopicName>depth/color/points</pointCloudTopicName>
        <cameraInfoTopicName>color/camera_info</cameraInfoTopicName>
        <depthImageCameraInfoTopicName>aligned_depth_to_color/camera_info</depthImageCameraInfoTopicName>
        <pointCloudCutoff>0.0</pointCloudCutoff>
        <hackBaseline>0.07</hackBaseline>
        <distortionK1>0.0</distortionK1>
        <distortionK2>0.0</distortionK2>
        <distortionK3>0.0</distortionK3>
        <distortionT1>0.0</distortionT1>
        <distortionT2>0.0</distortionT2>
        <CxPrime>0.0</CxPrime>
        <Cx>0.0</Cx>
        <Cy>0.0</Cy>
        <focalLength>0.0</focalLength>
      </plugin>
    </sensor>
  </gazebo>
  <gazebo reference="camera_infra1_frame">
    <sensor name="camera_infra1" type="multicamera">
      <always_on>1</always_on>
      <visualize>true</visualize>
      <update_rate>30</update_rate>
      <camera name="left">
        <horizontal_fov>1.5917</horizontal_fov>
        <image>
          <width>848</width>
          <height>480</height>
          <format>R8G8B8</format>
        </image>
        <clip>
          <near>0.02</near>
          <far>300</far>
        </clip>
        <noise>
          <type>gaussian</type>
          <mean>0.0</mean>
          <stddev>0.007</stddev>
        </noise>
      </camera>
      <camera name="right">
        <pose>0 -0.05 0 0 0 0</pose>
        <horizontal_fov>1.5917</horizontal_fov>
        <image>
          <width>848</width>
          <height>480</height>
          <format>R8G8B8</format>
        </image>
        <clip>
          <near>0.02</near>
          <far>300</far>
        </clip>
        <noise>
          <type>gaussian</type>
          <mean>0.0</mean>
          <stddev>0.007</stddev>
        </noise>
      </camera>
      <plugin filename="libgazebo_ros_multicamera.so" name="stereo_camera_controller">
        <alwaysOn>true</alwaysOn>
        <updateRate>0.0</updateRate>
        <cameraName>camera</cameraName>
        <imageTopicName>image_raw</imageTopicName>
        <cameraInfoTopicName>camera_info</cameraInfoTopicName>
        <frameName>camera_infra1_optical_frame</frameName>
        <rightFrameName>camera_infra2_optical_frame</rightFrameName>
        <hackBaseline>0.050</hackBaseline>
        <distortionK1>0.0</distortionK1>
        <distortionK2>0.0</distortionK2>
        <distortionK3>0.0</distortionK3>
        <distortionT1>0.0</distortionT1>
        <distortionT2>0.0</distortionT2>
      </plugin>
    </sensor>
  </gazebo>
  <!-- simulate_stereo -->
  <transmission name="JointTrans1">
    <type>transmission_interface/SimpleTransmission</type>
    <joint name="joint1">
      <hardwareInterface>hardware_interface/EffortJointInterface</hardwareInterface>
    </joint>
    <actuator name="Actuator1">
      <hardwareInterface>hardware_interface/EffortJointInterface</hardwareInterface>
      <mechanicalReduction>1</mechanicalReduction>
    </actuator>
  </transmission>
  <transmission name="JointTrans2">
    <type>transmission_interface/SimpleTransmission</type>
    <joint name="joint2">
      <hardwareInterface>hardware_interface/EffortJointInterface</hardwareInterface>
    </joint>
    <actuator name="Actuator2">
      <hardwareInterface>hardware_interface/EffortJointInterface</hardwareInterface>
      <mechanicalReduction>1</mechanicalReduction>
    </actuator>
  </transmission>
  <transmission name="JointTrans3">
    <type>transmission_interface/SimpleTransmission</type>
    <joint name="joint3">
      <hardwareInterface>hardware_interface/EffortJointInterface</hardwareInterface>
    </joint>
    <actuator name="Actuator3">
      <hardwareInterface>hardware_interface/EffortJointInterface</hardwareInterface>
      <mechanicalReduction>1</mechanicalReduction>
    </actuator>
  </transmission>
  <transmission name="JointTrans4">
    <type>transmission_interface/SimpleTransmission</type>
    <joint name="joint4">
      <hardwareInterface>hardware_interface/EffortJointInterface</hardwareInterface>
    </joint>
    <actuator name="Actuator4">
      <hardwareInterface>hardware_interface/EffortJointInterface</hardwareInterface>
      <mechanicalReduction>1</mechanicalReduction>
    </actuator>
  </transmission>
  <transmission name="JointTrans5">
    <type>transmission_interface/SimpleTransmission</type>
    <joint name="joint5">
      <hardwareInterface>hardware_interface/EffortJointInterface</hardwareInterface>
    </joint>
    <actuator name="Actuator5">
      <hardwareInterface>hardware_interface/EffortJointInterface</hardwareInterface>
      <mechanicalReduction>1</mechanicalReduction>
    </actuator>
  </transmission>
  <transmission name="JointTrans6">
    <type>transmission_interface/SimpleTransmission</type>
    <joint name="joint6">
      <hardwareInterface>hardware_interface/EffortJointInterface</hardwareInterface>
    </joint>
    <actuator name="Actuator6">
      <hardwareInterface>hardware_interface/EffortJointInterface</hardwareInterface>
      <mechanicalReduction>1</mechanicalReduction>
    </actuator>
  </transmission>
</robot>
